Workbook

Sheet Summary
B1: CHURCH FARM ROAD PUMP STATION & PIPELINE
B2: Material supply bid comparison · 4 supplier quotes · Washington City, Utah · prepared 9/29/2026
B4: COLOR KEY | C4: Lowest bid | D4: 2nd lowest | E4: Middle (3rd of 4) | F4: Highest bid | G4: Only one quote
B6: 1 · WHAT EACH SUPPLIER ACTUALLY QUOTED (the headline numbers — not comparable on their own)
B7: Supplier | C7: Quote / date | D7: Valid through | E7: Sum of transcribed lines | F7: Printed on quote (pre-tax) | G7: Difference | H7: Sales tax (quoted) | I7: Total incl. tax | J7: Lines | K7: Scope excluded from quote
B8: Ferguson | C8: Est. 006QQ000019fSKPYA2 · 9/18/26 | D8: ~10/18/26 (30 days) | E8: =SUMIFS('Quote Lines'!$I$3:$I$805,'Quote Lines'!$A$3:$A$805,$B8,'Quote Lines'!$M$3:$M$805,"Y") -> 1313834.4 | F8: 1313834.4 | G8: =E8-F8 -> 0 | H8: 88683.82 | I8: =F8+H8 -> 1402518.2 | J8: =COUNTIFS('Quote Lines'!$A$3:$A$805,$B8,'Quote Lines'!$M$3:$M$805,"Y") -> 207 | K8: Not guaranteed to be complete; award of ENTIRE BOM required; tariffs excluded
B9: HD Fowler | C9: Q647047 · bid date 9/9/26 | D9: Not stated | E9: =SUMIFS('Quote Lines'!$I$3:$I$805,'Quote Lines'!$A$3:$A$805,$B9,'Quote Lines'!$M$3:$M$805,"Y") -> 1036912.8 | F9: 1036912.8 | G9: =E9-F9 -> 0 | H9: 69991.77 | I9: =F9+H9 -> 1106904.6 | J9: =COUNTIFS('Quote Lines'!$A$3:$A$805,$B9,'Quote Lines'!$M$3:$M$805,"Y") -> 229 | K9: Casing pipe (no bid), spacers & end seals (TBD), bell restraints (qty by contractor), pipe supports, precast, steel fab
B10: Mountainland | C10: S108187947 · 9/16/26 | D10: 9/15/26 (before issue date) | E10: =SUMIFS('Quote Lines'!$I$3:$I$805,'Quote Lines'!$A$3:$A$805,$B10,'Quote Lines'!$M$3:$M$805,"Y") -> 1247235.1 | F10: 1247235.1 | G10: =E10-F10 -> 0 | H10: 84188.34 | I10: =F10+H10 -> 1331423.4 | J10: =COUNTIFS('Quote Lines'!$A$3:$A$805,$B10,'Quote Lines'!$M$3:$M$805,"Y") -> 173 | K10: Bid Items 1-4, 13, 15 no bid; owner supplies pumps & 12" meter/Cla-Val at vault
B11: Scholzen | C11: 7003117-00 · 7/24/26 | D11: 24 hours (expired 7/25/26) | E11: =SUMIFS('Quote Lines'!$I$3:$I$805,'Quote Lines'!$A$3:$A$805,$B11,'Quote Lines'!$M$3:$M$805,"Y") -> 1114950.3 | F11: 1114950.3 | G11: =E11-F11 -> 0 | H11: 78938.48 | I11: =F11+H11 -> 1193888.8 | J11: =COUNTIFS('Quote Lines'!$A$3:$A$805,$B11,'Quote Lines'!$M$3:$M$805,"Y") -> 183 | K11: Casing pipe, spacers, end seals; link seals 'not available'; spool lengths to be verified
B12: Printed totals are blue inputs read from each quote's last page; 'Difference' proves every line was transcribed. Sales tax is as quoted (Scholzen's implies 7.08% vs 6.75% on the other three).
B14: 2 · APPLES-TO-APPLES (same quantities for everyone; skipped items filled at the lowest competing price)
B15: Supplier | C15: Comparable rows priced | D15: Est. value of skipped rows | E15: Comparable-basis total | F15: vs. lowest ($) | G15: vs. lowest (%) | H15: Rank
B16: Ferguson | C16: =COUNTIFS('Material Comparison'!$AE$7:$AE$338,">=1",'Material Comparison'!$AE$7:$AE$338,"<=4")&" of "&COUNTIF('Material Comparison'!$S$7:$S$338,">=2") -> 155 of 177 | D16: =SUM('Material Comparison'!$AI$7:$AI$338)-SUMIFS('Material Comparison'!$K$7:$K$338,'Material Comparison'!$S$7:$S$338,">=2") -> 24598.41 | E16: =SUM('Material Comparison'!$AI$7:$AI$338) -> 1329066 | F16: =E16-MIN($E$16:$E$19) -> 54502.747 | G16: =E16/MIN($E$16:$E$19)-1 -> 0.042761899 | H16: =RANK(E16,$E$16:$E$19,1) -> 4
B17: HD Fowler | C17: =COUNTIFS('Material Comparison'!$AF$7:$AF$338,">=1",'Material Comparison'!$AF$7:$AF$338,"<=4")&" of "&COUNTIF('Material Comparison'!$S$7:$S$338,">=2") -> 145 of 177 | D17: =SUM('Material Comparison'!$AJ$7:$AJ$338)-SUMIFS('Material Comparison'!$L$7:$L$338,'Material Comparison'!$S$7:$S$338,">=2") -> 197167.62 | E17: =SUM('Material Comparison'!$AJ$7:$AJ$338) -> 1290937.8 | F17: =E17-MIN($E$16:$E$19) -> 16374.55 | G17: =E17/MIN($E$16:$E$19)-1 -> 0.012847185 | H17: =RANK(E17,$E$16:$E$19,1) -> 2
B18: Mountainland | C18: =COUNTIFS('Material Comparison'!$AG$7:$AG$338,">=1",'Material Comparison'!$AG$7:$AG$338,"<=4")&" of "&COUNTIF('Material Comparison'!$S$7:$S$338,">=2") -> 138 of 177 | D18: =SUM('Material Comparison'!$AK$7:$AK$338)-SUMIFS('Material Comparison'!$M$7:$M$338,'Material Comparison'!$S$7:$S$338,">=2") -> 52229.587 | E18: =SUM('Material Comparison'!$AK$7:$AK$338) -> 1274563.3 | F18: =E18-MIN($E$16:$E$19) -> 0 | G18: =E18/MIN($E$16:$E$19)-1 -> 0 | H18: =RANK(E18,$E$16:$E$19,1) -> 1
B19: Scholzen | C19: =COUNTIFS('Material Comparison'!$AH$7:$AH$338,">=1",'Material Comparison'!$AH$7:$AH$338,"<=4")&" of "&COUNTIF('Material Comparison'!$S$7:$S$338,">=2") -> 132 of 177 | D19: =SUM('Material Comparison'!$AL$7:$AL$338)-SUMIFS('Material Comparison'!$N$7:$N$338,'Material Comparison'!$S$7:$S$338,">=2") -> 208085.45 | E19: =SUM('Material Comparison'!$AL$7:$AL$338) -> 1293215.6 | F19: =E19-MIN($E$16:$E$19) -> 18652.298 | G19: =E19/MIN($E$16:$E$19)-1 -> 0.014634266 | H19: =RANK(E19,$E$16:$E$19,1) -> 3
B20: Comparable rows = material lines priced by at least two suppliers. Single-supplier lines (specialty spools, unique accessories) can't be compared and are excluded here.
B22: 3 · COLOR TALLY (how often each supplier lands in each color, across all comparable rows)
B23: Supplier | C23: Lowest (green) | D23: 2nd lowest (yellow) | E23: Middle (orange) | F23: Highest (red) | G23: Only quote | H23: Not quoted
B24: Ferguson | C24: =COUNTIF('Material Comparison'!$AE$7:$AE$338,1) -> 63 | D24: =COUNTIF('Material Comparison'!$AE$7:$AE$338,2) -> 18 | E24: =COUNTIF('Material Comparison'!$AE$7:$AE$338,3) -> 17 | F24: =COUNTIF('Material Comparison'!$AE$7:$AE$338,4) -> 57 | G24: =COUNTIF('Material Comparison'!$AE$7:$AE$338,5) -> 19 | H24: =COUNTIF('Material Comparison'!$AE$7:$AE$338,0) -> 132
B25: HD Fowler | C25: =COUNTIF('Material Comparison'!$AF$7:$AF$338,1) -> 48 | D25: =COUNTIF('Material Comparison'!$AF$7:$AF$338,2) -> 48 | E25: =COUNTIF('Material Comparison'!$AF$7:$AF$338,3) -> 25 | F25: =COUNTIF('Material Comparison'!$AF$7:$AF$338,4) -> 24 | G25: =COUNTIF('Material Comparison'!$AF$7:$AF$338,5) -> 35 | H25: =COUNTIF('Material Comparison'!$AF$7:$AF$338,0) -> 126
B26: Mountainland | C26: =COUNTIF('Material Comparison'!$AG$7:$AG$338,1) -> 48 | D26: =COUNTIF('Material Comparison'!$AG$7:$AG$338,2) -> 31 | E26: =COUNTIF('Material Comparison'!$AG$7:$AG$338,3) -> 25 | F26: =COUNTIF('Material Comparison'!$AG$7:$AG$338,4) -> 34 | G26: =COUNTIF('Material Comparison'!$AG$7:$AG$338,5) -> 30 | H26: =COUNTIF('Material Comparison'!$AG$7:$AG$338,0) -> 138
B27: Scholzen | C27: =COUNTIF('Material Comparison'!$AH$7:$AH$338,1) -> 18 | D27: =COUNTIF('Material Comparison'!$AH$7:$AH$338,2) -> 27 | E27: =COUNTIF('Material Comparison'!$AH$7:$AH$338,3) -> 24 | F27: =COUNTIF('Material Comparison'!$AH$7:$AH$338,4) -> 63 | G27: =COUNTIF('Material Comparison'!$AH$7:$AH$338,5) -> 45 | H27: =COUNTIF('Material Comparison'!$AH$7:$AH$338,0) -> 129
B28: Ties count for every tied supplier. 'Not quoted' = rows other suppliers priced that this supplier skipped.
B30: 4 · SPLIT-AWARD VIEW (buy every comparable line from its lowest bidder)
B31: Supplier | C31: Lines won | D31: $ awarded | E31: Share of split total
B32: Ferguson | C32: =COUNTIF('Material Comparison'!$AQ$7:$AQ$338,$B32) -> 63 | D32: =SUMIFS('Material Comparison'!$AP$7:$AP$338,'Material Comparison'!$AQ$7:$AQ$338,$B32) -> 695002.58 | E32: =D32/$D$36 -> 0.57683141
B33: HD Fowler | C33: =COUNTIF('Material Comparison'!$AQ$7:$AQ$338,$B33) -> 48 | D33: =SUMIFS('Material Comparison'!$AP$7:$AP$338,'Material Comparison'!$AQ$7:$AQ$338,$B33) -> 210897.75 | E33: =D33/$D$36 -> 0.17503884
B34: Mountainland | C34: =COUNTIF('Material Comparison'!$AQ$7:$AQ$338,$B34) -> 48 | D34: =SUMIFS('Material Comparison'!$AP$7:$AP$338,'Material Comparison'!$AQ$7:$AQ$338,$B34) -> 170346.29 | E34: =D34/$D$36 -> 0.14138233
B35: Scholzen | C35: =COUNTIF('Material Comparison'!$AQ$7:$AQ$338,$B35) -> 18 | D35: =SUMIFS('Material Comparison'!$AP$7:$AP$338,'Material Comparison'!$AQ$7:$AQ$338,$B35) -> 128615.97 | E35: =D35/$D$36 -> 0.10674742
B36: Split total | C36: =SUM(C32:C35) -> 177 | D36: =SUM(D32:D35) -> 1204862.6 | E36: =SUM(E32:E35) -> 1
B37: Best single-supplier total (section 2) | D37: =MIN(E16:E19) -> 1274563.3
B38: Potential saving from splitting | D38: =D37-D36 -> 69700.701 | E38: =D38/D37 -> 0.054685947
B39: Middle path: award each BID ITEM to its cheapest supplier | D39: =SUM('By Bid Item'!H5:H30) -> 1242308.5 | E39: =D37-D39 -> 32254.758
B40: Caveat: Ferguson's quote is 'contingent upon award of entire bill of materials' — splitting the buy can void its unit prices. Ties are awarded to the first supplier listed.
B42: 5 · CLEAN HEAD-TO-HEAD (only rows all four suppliers priced — no gap-filling, no judgment calls)
B43: Supplier | C43: Rows in basket | D43: Basket total | E43: vs. lowest (%)
B44: Ferguson | C44: =COUNTIF('Material Comparison'!$S$7:$S$338,4) -> 92 | D44: =SUMIFS('Material Comparison'!$K$7:$K$338,'Material Comparison'!$S$7:$S$338,4) -> 1047651.1 | E44: =IFERROR(D44/MIN($D$44:$D$47)-1,0) -> 0.052118452
B45: HD Fowler | C45: =COUNTIF('Material Comparison'!$S$7:$S$338,4) -> 92 | D45: =SUMIFS('Material Comparison'!$L$7:$L$338,'Material Comparison'!$S$7:$S$338,4) -> 1028533.5 | E45: =IFERROR(D45/MIN($D$44:$D$47)-1,0) -> 0.032919368
B46: Mountainland | C46: =COUNTIF('Material Comparison'!$S$7:$S$338,4) -> 92 | D46: =SUMIFS('Material Comparison'!$M$7:$M$338,'Material Comparison'!$S$7:$S$338,4) -> 995753.93 | E46: =IFERROR(D46/MIN($D$44:$D$47)-1,0) -> 0
...

Sheet Material Comparison
A1: CHURCH FARM ROAD PUMP STATION & PIPELINE — MATERIAL BID COMPARISON
A2: Washington City, Utah · 4 supplier quotes · unit prices normalized to a common UoM · Extended = unit price × Ref Qty (blue, editable) so every supplier is compared on the same quantity
A3: KEY: | D3: Lowest bid | G3: 2nd lowest | I3: Middle (3rd of 4) | K3: Highest bid | M3: Only one quote | O3: — = not quoted | V3: 3 quotes → green / yellow / red · 2 quotes → green / red · ties share the better color · blue cells are inputs
A4: Tip: filter column T to 'Like-for-like' for the cleanest head-to-head; expand the [+] group above column W for each supplier's own quoted quantities.
A5: MATERIAL | G5: UNIT PRICE ($ per UoM) | K5: EXTENDED @ REF QTY ($) | O5: ANALYSIS | V5: NOTES / SPEC FLAGS | W5: QUOTED QTY (each supplier's own takeoff)
A6: Row | B6: Bid item | C6: Group | D6: Material | E6: UoM | F6: Ref qty | G6: Ferguson | H6: HD Fowler | I6: Mountainland | J6: Scholzen | K6: Ferguson | L6: HD Fowler | M6: Mountainland | N6: Scholzen | O6: Lowest unit ($) | P6: Best supplier | Q6: High vs low | R6: $ spread @ ref qty | S6: # quotes | T6: Comparability | U6: Qty check | V6: Notes | W6: Ferguson | X6: HD Fowler | Y6: Mountainland | Z6: Scholzen | AA6: Rank: Ferguson | AB6: Rank: HD Fowler | AC6: Rank: Mountainland | AD6: Rank: Scholzen | AE6: Color code: Ferguson | AF6: Color code: HD Fowler | AG6: Color code: Mountainland | AH6: Color code: Scholzen | AI6: Comparable-basis ext: Ferguson | AJ6: Comparable-basis ext: HD Fowler | AK6: Comparable-basis ext: Mountainland | AL6: Comparable-basis ext: Scholzen | AM6: Spread key | AN6: Highest unit | AO6: Highest supplier | AP6: Best ext | AQ6: Winner (first)
B7: BID ITEM 5 — Pump station, meter vault & valve vault
A8: R001 | B8: Item 5 | C8: DI fittings | D8: 16" flanged 90° elbow | E8: EA | F8: 2 | G8: =IF(COUNTIF('Quote Lines'!$P$3:$P$805,$A8&"|"&G$6&"|1")=0,"—",SUMIFS('Quote Lines'!$O$3:$O$805,'Quote Lines'!$P$3:$P$805,$A8&"|"&G$6&"|1")/SUMIFS('Quote Lines'!$L$3:$L$805,'Quote Lines'!$P$3:$P$805,$A8&"|"&G$6&"|1")) -> 1493.17 | H8: =IF(COUNTIF('Quote Lines'!$P$3:$P$805,$A8&"|"&H$6&"|1")=0,"—",SUMIFS('Quote Lines'!$O$3:$O$805,'Quote Lines'!$P$3:$P$805,$A8&"|"&H$6&"|1")/SUMIFS('Quote Lines'!$L$3:$L$805,'Quote Lines'!$P$3:$P$805,$A8&"|"&H$6&"|1")) -> 1560.11 | I8: =IF(COUNTIF('Quote Lines'!$P$3:$P$805,$A8&"|"&I$6&"|1")=0,"—",SUMIFS('Quote Lines'!$O$3:$O$805,'Quote Lines'!$P$3:$P$805,$A8&"|"&I$6&"|1")/SUMIFS('Quote Lines'!$L$3:$L$805,'Quote Lines'!$P$3:$P$805,$A8&"|"&I$6&"|1")) -> 1693.9 | J8: =IF(COUNTIF('Quote Lines'!$P$3:$P$805,$A8&"|"&J$6&"|1")=0,"—",SUMIFS('Quote Lines'!$O$3:$O$805,'Quote Lines'!$P$3:$P$805,$A8&"|"&J$6&"|1")/SUMIFS('Quote Lines'!$L$3:$L$805,'Quote Lines'!$P$3:$P$805,$A8&"|"&J$6&"|1")) -> 1634 | K8: =IF(ISNUMBER(G8),G8*$F8,"—") -> 2986.34 | L8: =IF(ISNUMBER(H8),H8*$F8,"—") -> 3120.22 | M8: =IF(ISNUMBER(I8),I8*$F8,"—") -> 3387.8 | N8: =IF(ISNUMBER(J8),J8*$F8,"—") -> 3268 | O8: =IF($S8=0,"—",MIN(G8:J8)) -> 1493.17 | P8: =IF($S8=0,"—",IF(COUNTIF(G8:J8,O8)>1,"Tie",INDEX($G$6:$J$6,MATCH(O8,G8:J8,0)))) -> Ferguson | Q8: =IF($S8>=2,MAX(G8:J8)/MIN(G8:J8)-1,"—") -> 0.13443211 | R8: =IF($S8>=2,(MAX(G8:J8)-MIN(G8:J8))*$F8,"—") -> 401.46 | S8: =COUNT(G8:J8) -> 4 | T8: =IF($S8<=1,IF($S8=1,"Single quote","—"),"Like-for-like") -> Like-for-like | U8: =IF(COUNT(W8:Z8)<2,"",IF(MAX(W8:Z8)=MIN(W8:Z8),"OK","Qty differs")) -> OK | W8: =IF(COUNTIFS('Quote Lines'!$P$3:$P$805,$A8&"|"&G$6&"|1",'Quote Lines'!$M$3:$M$805,"Y")=0,"",SUMIFS('Quote Lines'!$L$3:$L$805,'Quote Lines'!$P$3:$P$805,$A8&"|"&G$6&"|1",'Quote Lines'!$M$3:$M$805,"Y")) -> 2 | X8: =IF(COUNTIFS('Quote Lines'!$P$3:$P$805,$A8&"|"&H$6&"|1",'Quote Lines'!$M$3:$M$805,"Y")=0,"",SUMIFS('Quote Lines'!$L$3:$L$805,'Quote Lines'!$P$3:$P$805,$A8&"|"&H$6&"|1",'Quote Lines'!$M$3:$M$805,"Y")) -> 2 | Y8: =IF(COUNTIFS('Quote Lines'!$P$3:$P$805,$A8&"|"&I$6&"|1",'Quote Lines'!$M$3:$M$805,"Y")=0,"",SUMIFS('Quote Lines'!$L$3:$L$805,'Quote Lines'!$P$3:$P$805,$A8&"|"&I$6&"|1",'Quote Lines'!$M$3:$M$805,"Y")) -> 2 | Z8: =IF(COUNTIFS('Quote Lines'!$P$3:$P$805,$A8&"|"&J$6&"|1",'Quote Lines'!$M$3:$M$805,"Y")=0,"",SUMIFS('Quote Lines'!$L$3:$L$805,'Quote Lines'!$P$3:$P$805,$A8&"|"&J$6&"|1",'Quote Lines'!$M$3:$M$805,"Y")) -> 2 | AA8: =IF(ISNUMBER(G8),1+SUMPRODUCT(ISNUMBER($G8:$J8)*($G8:$J8<G8)),"") -> 1 | AB8: =IF(ISNUMBER(H8),1+SUMPRODUCT(ISNUMBER($G8:$J8)*($G8:$J8<H8)),"") -> 2 | AC8: =IF(ISNUMBER(I8),1+SUMPRODUCT(ISNUMBER($G8:$J8)*($G8:$J8<I8)),"") -> 4 | AD8: =IF(ISNUMBER(J8),1+SUMPRODUCT(ISNUMBER($G8:$J8)*($G8:$J8<J8)),"") -> 3 | AE8: =IF(NOT(ISNUMBER(G8)),0,IF($S8<2,5,IF(AA8=1,1,IF(G8=MAX($G8:$J8),4,IF(AA8=2,2,3))))) -> 1 | AF8: =IF(NOT(ISNUMBER(H8)),0,IF($S8<2,5,IF(AB8=1,1,IF(H8=MAX($G8:$J8),4,IF(AB8=2,2,3))))) -> 2 | AG8: =IF(NOT(ISNUMBER(I8)),0,IF($S8<2,5,IF(AC8=1,1,IF(I8=MAX($G8:$J8),4,IF(AC8=2,2,3))))) -> 4 | AH8: =IF(NOT(ISNUMBER(J8)),0,IF($S8<2,5,IF(AD8=1,1,IF(J8=MAX($G8:$J8),4,IF(AD8=2,2,3))))) -> 3 | AI8: =IF($S8>=2,IF(ISNUMBER(G8),G8*$F8,MIN($G8:$J8)*$F8),0) -> 2986.34 | AJ8: =IF($S8>=2,IF(ISNUMBER(H8),H8*$F8,MIN($G8:$J8)*$F8),0) -> 3120.22 | AK8: =IF($S8>=2,IF(ISNUMBER(I8),I8*$F8,MIN($G8:$J8)*$F8),0) -> 3387.8 | AL8: =IF($S8>=2,IF(ISNUMBER(J8),J8*$F8,MIN($G8:$J8)*$F8),0) -> 3268 | AM8: =IF($S8>=2,$R8+ROW()/1000000,"") -> 401.46001 | AN8: =IF($S8>=2,MAX(G8:J8),"") -> 1693.9 | AO8: =IF($S8>=2,INDEX($G$6:$J$6,MATCH(MAX(G8:J8),G8:J8,0)),"") -> Mountainland | AP8: =IF($S8>=2,MIN(G8:J8)*$F8,0) -> 2986.34 | AQ8: =IF($S8>=2,INDEX($G$6:$J$6,MATCH(MIN(G8:J8),G8:J8,0)),"") -> Ferguson
A9: R002 | B9: Item 5 | C9: DI fittings | D9: 16" x 10" flanged concentric reducer | E9: EA | F9: 2 | G9: =IF(COUNTIF('Quote Lines'!$P$3:$P$805,$A9&"|"&G$6&"|1")=0,"—",SUMIFS('Quote Lines'!$O$3:$O$805,'Quote Lines'!$P$3:$P$805,$A9&"|"&G$6&"|1")/SUMIFS('Quote Lines'!$L$3:$L$805,'Quote Lines'!$P$3:$P$805,$A9&"|"&G$6&"|1")) -> 946.86 | H9: =IF(COUNTIF('Quote Lines'!$P$3:$P$805,$A9&"|"&H$6&"|1")=0,"—",SUMIFS('Quote Lines'!$O$3:$O$805,'Quote Lines'!$P$3:$P$805,$A9&"|"&H$6&"|1")/SUMIFS('Quote Lines'!$L$3:$L$805,'Quote Lines'!$P$3:$P$805,$A9&"|"&H$6&"|1")) -> 989.3 | I9: =IF(COUNTIF('Quote Lines'!$P$3:$P$805,$A9&"|"&I$6&"|1")=0,"—",SUMIFS('Quote Lines'!$O$3:$O$805,'Quote Lines'!$P$3:$P$805,$A9&"|"&I$6&"|1")/SUMIFS('Quote Lines'!$L$3:$L$805,'Quote Lines'!$P$3:$P$805,$A9&"|"&I$6&"|1")) -> 1074.145 | J9: =IF(COUNTIF('Quote Lines'!$P$3:$P$805,$A9&"|"&J$6&"|1")=0,"—",SUMIFS('Quote Lines'!$O$3:$O$805,'Quote Lines'!$P$3:$P$805,$A9&"|"&J$6&"|1")/SUMIFS('Quote Lines'!$L$3:$L$805,'Quote Lines'!$P$3:$P$805,$A9&"|"&J$6&"|1")) -> 1054.02 | K9: =IF(ISNUMBER(G9),G9*$F9,"—") -> 1893.72 | L9: =IF(ISNUMBER(H9),H9*$F9,"—") -> 1978.6 | M9: =IF(ISNUMBER(I9),I9*$F9,"—") -> 2148.29 | N9: =IF(ISNUMBER(J9),J9*$F9,"—") -> 2108.04 | O9: =IF($S9=0,"—",MIN(G9:J9)) -> 946.86 | P9: =IF($S9=0,"—",IF(COUNTIF(G9:J9,O9)>1,"Tie",INDEX($G$6:$J$6,MATCH(O9,G9:J9,0)))) -> Ferguson | Q9: =IF($S9>=2,MAX(G9:J9)/MIN(G9:J9)-1,"—") -> 0.13442853 | R9: =IF($S9>=2,(MAX(G9:J9)-MIN(G9:J9))*$F9,"—") -> 254.57 | S9: =COUNT(G9:J9) -> 4 | T9: =IF($S9<=1,IF($S9=1,"Single quote","—"),"Like-for-like") -> Like-for-like | U9: =IF(COUNT(W9:Z9)<2,"",IF(MAX(W9:Z9)=MIN(W9:Z9),"OK","Qty differs")) -> OK | W9: =IF(COUNTIFS('Quote Lines'!$P$3:$P$805,$A9&"|"&G$6&"|1",'Quote Lines'!$M$3:$M$805,"Y")=0,"",SUMIFS('Quote Lines'!$L$3:$L$805,'Quote Lines'!$P$3:$P$805,$A9&"|"&G$6&"|1",'Quote Lines'!$M$3:$M$805,"Y")) -> 2 | X9: =IF(COUNTIFS('Quote Lines'!$P$3:$P$805,$A9&"|"&H$6&"|1",'Quote Lines'!$M$3:$M$805,"Y")=0,"",SUMIFS('Quote Lines'!$L$3:$L$805,'Quote Lines'!$P$3:$P$805,$A9&"|"&H$6&"|1",'Quote Lines'!$M$3:$M$805,"Y")) -> 2 | Y9: =IF(COUNTIFS('Quote Lines'!$P$3:$P$805,$A9&"|"&I$6&"|1",'Quote Lines'!$M$3:$M$805,"Y")=0,"",SUMIFS('Quote Lines'!$L$3:$L$805,'Quote Lines'!$P$3:$P$805,$A9&"|"&I$6&"|1",'Quote Lines'!$M$3:$M$805,"Y")) -> 2 | Z9: =IF(COUNTIFS('Quote Lines'!$P$3:$P$805,$A9&"|"&J$6&"|1",'Quote Lines'!$M$3:$M$805,"Y")=0,"",SUMIFS('Quote Lines'!$L$3:$L$805,'Quote Lines'!$P$3:$P$805,$A9&"|"&J$6&"|1",'Quote Lines'!$M$3:$M$805,"Y")) -> 2 | AA9: =IF(ISNUMBER(G9),1+SUMPRODUCT(ISNUMBER($G9:$J9)*($G9:$J9<G9)),"") -> 1 | AB9: =IF(ISNUMBER(H9),1+SUMPRODUCT(ISNUMBER($G9:$J9)*($G9:$J9<H9)),"") -> 2 | AC9: =IF(ISNUMBER(I9),1+SUMPRODUCT(ISNUMBER($G9:$J9)*($G9:$J9<I9)),"") -> 4 | AD9: =IF(ISNUMBER(J9),1+SUMPRODUCT(ISNUMBER($G9:$J9)*($G9:$J9<J9)),"") -> 3 | AE9: =IF(NOT(ISNUMBER(G9)),0,IF($S9<2,5,IF(AA9=1,1,IF(G9=MAX($G9:$J9),4,IF(AA9=2,2,3))))) -> 1 | AF9: =IF(NOT(ISNUMBER(H9)),0,IF($S9<2,5,IF(AB9=1,1,IF(H9=MAX($G9:$J9),4,IF(AB9=2,2,3))))) -> 2 | AG9: =IF(NOT(ISNUMBER(I9)),0,IF($S9<2,5,IF(AC9=1,1,IF(I9=MAX($G9:$J9),4,IF(AC9=2,2,3))))) -> 4 | AH9: =IF(NOT(ISNUMBER(J9)),0,IF($S9<2,5,IF(AD9=1,1,IF(J9=MAX($G9:$J9),4,IF(AD9=2,2,3))))) -> 3 | AI9: =IF($S9>=2,IF(ISNUMBER(G9),G9*$F9,MIN($G9:$J9)*$F9),0) -> 1893.72 | AJ9: =IF($S9>=2,IF(ISNUMBER(H9),H9*$F9,MIN($G9:$J9)*$F9),0) -> 1978.6 | AK9: =IF($S9>=2,IF(ISNUMBER(I9),I9*$F9,MIN($G9:$J9)*$F9),0) -> 2148.29 | AL9: =IF($S9>=2,IF(ISNUMBER(J9),J9*$F9,MIN($G9:$J9)*$F9),0) -> 2108.04 | AM9: =IF($S9>=2,$R9+ROW()/1000000,"") -> 254.57001 | AN9: =IF($S9>=2,MAX(G9:J9),"") -> 1074.145 | AO9: =IF($S9>=2,INDEX($G$6:$J$6,MATCH(MAX(G9:J9),G9:J9,0)),"") -> Mountainland | AP9: =IF($S9>=2,MIN(G9:J9)*$F9,0) -> 1893.72 | AQ9: =IF($S9>=2,INDEX($G$6:$J$6,MATCH(MIN(G9:J9),G9:J9,0)),"") -> Ferguson
A10: R003 | B10: Item 5 | C10: DI fittings | D10: 16" x 12" flanged concentric reducer | E10: EA | F10: 1 | G10: — | H10: =IF(COUNTIF('Quote Lines'!$P$3:$P$805,$A10&"|"&H$6&"|1")=0,"—",SUMIFS('Quote Lines'!$O$3:$O$805,'Quote Lines'!$P$3:$P$805,$A10&"|"&H$6&"|1")/SUMIFS('Quote Lines'!$L$3:$L$805,'Quote Lines'!$P$3:$P$805,$A10&"|"&H$6&"|1")) -> 1309.41 | I10: — | J10: =IF(COUNTIF('Quote Lines'!$P$3:$P$805,$A10&"|"&J$6&"|1")=0,"—",SUMIFS('Quote Lines'!$O$3:$O$805,'Quote Lines'!$P$3:$P$805,$A10&"|"&J$6&"|1")/SUMIFS('Quote Lines'!$L$3:$L$805,'Quote Lines'!$P$3:$P$805,$A10&"|"&J$6&"|1")) -> 1395.07 | K10: =IF(ISNUMBER(G10),G10*$F10,"—") -> — | L10: =IF(ISNUMBER(H10),H10*$F10,"—") -> 1309.41 | M10: =IF(ISNUMBER(I10),I10*$F10,"—") -> — | N10: =IF(ISNUMBER(J10),J10*$F10,"—") -> 1395.07 | O10: =IF($S10=0,"—",MIN(G10:J10)) -> 1309.41 | P10: =IF($S10=0,"—",IF(COUNTIF(G10:J10,O10)>1,"Tie",INDEX($G$6:$J$6,MATCH(O10,G10:J10,0)))) -> HD Fowler | Q10: =IF($S10>=2,MAX(G10:J10)/MIN(G10:J10)-1,"—") -> 0.065418776 | R10: =IF($S10>=2,(MAX(G10:J10)-MIN(G10:J10))*$F10,"—") -> 85.66 | S10: =COUNT(G10:J10) -> 2 | T10: =IF($S10<=1,IF($S10=1,"Single quote","—"),"Like-for-like") -> Like-for-like | U10: =IF(COUNT(W10:Z10)<2,"",IF(MAX(W10:Z10)=MIN(W10:Z10),"OK","Qty differs")) -> OK | V10: Ferguson quoted MJ-end 16x12 reducers instead (next row). | X10: =IF(COUNTIFS('Quote Lines'!$P$3:$P$805,$A10&"|"&H$6&"|1",'Quote Lines'!$M$3:$M$805,"Y")=0,"",SUMIFS('Quote Lines'!$L$3:$L$805,'Quote Lines'!$P$3:$P$805,$A10&"|"&H$6&"|1",'Quote Lines'!$M$3:$M$805,"Y")) -> 1 | Z10: =IF(COUNTIFS('Quote Lines'!$P$3:$P$805,$A10&"|"&J$6&"|1",'Quote Lines'!$M$3:$M$805,"Y")=0,"",SUMIFS('Quote Lines'!$L$3:$L$805,'Quote Lines'!$P$3:$P$805,$A10&"|"&J$6&"|1",'Quote Lines'!$M$3:$M$805,"Y")) -> 1 | AA10: =IF(ISNUMBER(G10),1+SUMPRODUCT(ISNUMBER($G10:$J10)*($G10:$J10<G10)),"") | AB10: =IF(ISNUMBER(H10),1+SUMPRODUCT(ISNUMBER($G10:$J10)*($G10:$J10<H10)),"") -> 1 | AC10: =IF(ISNUMBER(I10),1+SUMPRODUCT(ISNUMBER($G10:$J10)*($G10:$J10<I10)),"") | AD10: =IF(ISNUMBER(J10),1+SUMPRODUCT(ISNUMBER($G10:$J10)*($G10:$J10<J10)),"") -> 2 | AE10: =IF(NOT(ISNUMBER(G10)),0,IF($S10<2,5,IF(AA10=1,1,IF(G10=MAX($G10:$J10),4,IF(AA10=2,2,3))))) -> 0 | AF10: =IF(NOT(ISNUMBER(H10)),0,IF($S10<2,5,IF(AB10=1,1,IF(H10=MAX($G10:$J10),4,IF(AB10=2,2,3))))) -> 1 | AG10: =IF(NOT(ISNUMBER(I10)),0,IF($S10<2,5,IF(AC10=1,1,IF(I10=MAX($G10:$J10),4,IF(AC10=2,2,3))))) -> 0 | AH10: =IF(NOT(ISNUMBER(J10)),0,IF($S10<2,5,IF(AD10=1,1,IF(J10=MAX($G10:$J10),4,IF(AD10=2,2,3))))) -> 4 | AI10: =IF($S10>=2,IF(ISNUMBER(G10),G10*$F10,MIN($G10:$J10)*$F10),0) -> 1309.41 | AJ10: =IF($S10>=2,IF(ISNUMBER(H10),H10*$F10,MIN($G10:$J10)*$F10),0) -> 1309.41 | AK10: =IF($S10>=2,IF(ISNUMBER(I10),I10*$F10,MIN($G10:$J10)*$F10),0) -> 1309.41 | AL10: =IF($S10>=2,IF(ISNUMBER(J10),J10*$F10,MIN($G10:$J10)*$F10),0) -> 1395.07 | AM10: =IF($S10>=2,$R10+ROW()/1000000,"") -> 85.66001 | AN10: =IF($S10>=2,MAX(G10:J10),"") -> 1395.07 | AO10: =IF($S10>=2,INDEX($G$6:$J$6,MATCH(MAX(G10:J10),G10:J10,0)),"") -> Scholzen | AP10: =IF($S10>=2,MIN(G10:J10)*$F10,0) -> 1309.41 | AQ10: =IF($S10>=2,INDEX($G$6:$J$6,MATCH(MIN(G10:J10),G10:J10,0)),"") -> HD Fowler
A11: R004 | B11: Item 5 | C11: DI fittings | D11: 16" x 12" MJ reducer (all-bell / large-end) | E11: EA | F11: 2 | G11: =IF(COUNTIF('Quote Lines'!$P$3:$P$805,$A11&"|"&G$6&"|1")=0,"—",SUMIFS('Quote Lines'!$O$3:$O$805,'Quote Lines'!$P$3:$P$805,$A11&"|"&G$6&"|1")/SUMIFS('Quote Lines'!$L$3:$L$805,'Quote Lines'!$P$3:$P$805,$A11&"|"&G$6&"|1")) -> 519.874 | H11: =IF(COUNTIF('Quote Lines'!$P$3:$P$805,$A11&"|"&H$6&"|1")=0,"—",SUMIFS('Quote Lines'!$O$3:$O$805,'Quote Lines'!$P$3:$P$805,$A11&"|"&H$6&"|1")/SUMIFS('Quote Lines'!$L$3:$L$805,'Quote Lines'!$P$3:$P$805,$A11&"|"&H$6&"|1")) -> 542.5 | I11: =IF(COUNTIF('Quote Lines'!$P$3:$P$805,$A11&"|"&I$6&"|1")=0,"—",SUMIFS('Quote Lines'!$O$3:$O$805,'Quote Lines'!$P$3:$P$805,$A11&"|"&I$6&"|1")/SUMIFS('Quote Lines'!$L$3:$L$805,'Quote Lines'!$P$3:$P$805,$A11&"|"&I$6&"|1")) -> 589.02333 | J11: =IF(COUNTIF('Quote Lines'!$P$3:$P$805,$A11&"|"&J$6&"|1")=0,"—",SUMIFS('Quote Lines'!$O$3:$O$805,'Quote Lines'!$P$3:$P$805,$A11&"|"&J$6&"|1")/SUMIFS('Quote Lines'!$L$3:$L$805,'Quote Lines'!$P$3:$P$805,$A11&"|"&J$6&"|1")) -> 568 | K11: =IF(ISNUMBER(G11),G11*$F11,"—") -> 1039.748 | L11: =IF(ISNUMBER(H11),H11*$F11,"—") -> 1085 | M11: =IF(ISNUMBER(I11),I11*$F11,"—") -> 1178.0467 | N11: =IF(ISNUMBER(J11),J11*$F11,"—") -> 1136 | O11: =IF($S11=0,"—",MIN(G11:J11)) -> 519.874 | P11: =IF($S11=0,"—",IF(COUNTIF(G11:J11,O11)>1,"Tie",INDEX($G$6:$J$6,MATCH(O11,G11:J11,0)))) -> Ferguson | Q11: =IF($S11>=2,MAX(G11:J11)/MIN(G11:J11)-1,"—") -> 0.13301172 | R11: =IF($S11>=2,(MAX(G11:J11)-MIN(G11:J11))*$F11,"—") -> 138.29867 | S11: =COUNT(G11:J11) -> 4 | T11: =IF($S11<=1,IF($S11=1,"Single quote","—"),"Alt spec – verify") -> Alt spec – verify | U11: =IF(COUNT(W11:Z11)<2,"",IF(MAX(W11:Z11)=MIN(W11:Z11),"OK","Qty differs")) -> Qty differs | V11: Ferguson mixes all-bell and large-end MJ reducers; H = 'MJ BXB'. Quantities differ by takeoff. | W11: =IF(COUNTIFS('Quote Lines'!$P$3:$P$805,$A11&"|"&G$6&"|1",'Quote Lines'!$M$3:$M$805,"Y")=0,"",SUMIFS('Quote Lines'!$L$3:$L$805,'Quote Lines'!$P$3:$P$805,$A11&"|"&G$6&"|1",'Quote Lines'!$M$3:$M$805,"Y")) -> 5 | X11: =IF(COUNTIFS('Quote Lines'!$P$3:$P$805,$A11&"|"&H$6&"|1",'Quote Lines'!$M$3:$M$805,"Y")=0,"",SUMIFS('Quote Lines'!$L$3:$L$805,'Quote Lines'!$P$3:$P$805,$A11&"|"&H$6&"|1",'Quote Lines'!$M$3:$M$805,"Y")) -> 2 | Y11: =IF(COUNTIFS('Quote Lines'!$P$3:$P$805,$A11&"|"&I$6&"|1",'Quote Lines'!$M$3:$M$805,"Y")=0,"",SUMIFS('Quote Lines'!$L$3:$L$805,'Quote Lines'!$P$3:$P$805,$A11&"|"&I$6&"|1",'Quote Lines'!$M$3:$M$805,"Y")) -> 3 | Z11: =IF(COUNTIFS('Quote Lines'!$P$3:$P$805,$A11&"|"&J$6&"|1",'Quote Lines'!$M$3:$M$805,"Y")=0,"",SUMIFS('Quote Lines'!$L$3:$L$805,'Quote Lines'!$P$3:$P$805,$A11&"|"&J$6&"|1",'Quote Lines'!$M$3:$M$805,"Y")) -> 2 | AA11: =IF(ISNUMBER(G11),1+SUMPRODUCT(ISNUMBER($G11:$J11)*($G11:$J11<G11)),"") -> 1 | AB11: =IF(ISNUMBER(H11),1+SUMPRODUCT(ISNUMBER($G11:$J11)*($G11:$J11<H11)),"") -> 2 | AC11: =IF(ISNUMBER(I11),1+SUMPRODUCT(ISNUMBER($G11:$J11)*($G11:$J11<I11)),"") -> 4 | AD11: =IF(ISNUMBER(J11),1+SUMPRODUCT(ISNUMBER($G11:$J11)*($G11:$J11<J11)),"") -> 3 | AE11: =IF(NOT(ISNUMBER(G11)),0,IF($S11<2,5,IF(AA11=1,1,IF(G11=MAX($G11:$J11),4,IF(AA11=2,2,3))))) -> 1 | AF11: =IF(NOT(ISNUMBER(H11)),0,IF($S11<2,5,IF(AB11=1,1,IF(H11=MAX($G11:$J11),4,IF(AB11=2,2,3))))) -> 2 | AG11: =IF(NOT(ISNUMBER(I11)),0,IF($S11<2,5,IF(AC11=1,1,IF(I11=MAX($G11:$J11),4,IF(AC11=2,2,3))))) -> 4 | AH11: =IF(NOT(ISNUMBER(J11)),0,IF($S11<2,5,IF(AD11=1,1,IF(J11=MAX($G11:$J11),4,IF(AD11=2,2,3))))) -> 3 | AI11: =IF($S11>=2,IF(ISNUMBER(G11),G11*$F11,MIN($G11:$J11)*$F11),0) -> 1039.748 | AJ11: =IF($S11>=2,IF(ISNUMBER(H11),H11*$F11,MIN($G11:$J11)*$F11),0) -> 1085 | AK11: =IF($S11>=2,IF(ISNUMBER(I11),I11*$F11,MIN($G11:$J11)*$F11),0) -> 1178.0467 | AL11: =IF($S11>=2,IF(ISNUMBER(J11),J11*$F11,MIN($G11:$J11)*$F11),0) -> 1136 | AM11: =IF($S11>=2,$R11+ROW()/1000000,"") -> 138.29868 | AN11: =IF($S11>=2,MAX(G11:J11),"") -> 589.02333 | AO11: =IF($S11>=2,INDEX($G$6:$J$6,MATCH(MAX(G11:J11),G11:J11,0)),"") -> Mountainland | AP11: =IF($S11>=2,MIN(G11:J11)*$F11,0) -> 1039.748 | AQ11: =IF($S11>=2,INDEX($G$6:$J$6,MATCH(MIN(G11:J11),G11:J11,0)),"") -> Ferguson
A12: R005 | B12: Item 5 | C12: DI fittings | D12: 12" flanged tee | E12: EA | F12: 1 | G12: =IF(COUNTIF('Quote Lines'!$P$3:$P$805,$A12&"|"&G$6&"|1")=0,"—",SUMIFS('Quote Lines'!$O$3:$O$805,'Quote Lines'!$P$3:$P$805,$A12&"|"&G$6&"|1")/SUMIFS('Quote Lines'!$L$3:$L$805,'Quote Lines'!$P$3:$P$805,$A12&"|"&G$6&"|1")) -> 1468.02 | H12: =IF(COUNTIF('Quote Lines'!$P$3:$P$805,$A12&"|"&H$6&"|1")=0,"—",SUMIFS('Quote Lines'!$O$3:$O$805,'Quote Lines'!$P$3:$P$805,$A12&"|"&H$6&"|1")/SUMIFS('Quote Lines'!$L$3:$L$805,'Quote Lines'!$P$3:$P$805,$A12&"|"&H$6&"|1")) -> 1533.83 | I12: — | J12: =IF(COUNTIF('Quote Lines'!$P$3:$P$805,$A12&"|"&J$6&"|1")=0,"—",SUMIFS('Quote Lines'!$O$3:$O$805,'Quote Lines'!$P$3:$P$805,$A12&"|"&J$6&"|1")/SUMIFS('Quote Lines'!$L$3:$L$805,'Quote Lines'!$P$3:$P$805,$A12&"|"&J$6&"|1")) -> 1707 | K12: =IF(ISNUMBER(G12),G12*$F12,"—") -> 1468.02 | L12: =IF(ISNUMBER(H12),H12*$F12,"—") -> 1533.83 | M12: =IF(ISNUMBER(I12),I12*$F12,"—") -> — | N12: =IF(ISNUMBER(J12),J12*$F12,"—") -> 1707 | O12: =IF($S12=0,"—",MIN(G12:J12)) -> 1468.02 | P12: =IF($S12=0,"—",IF(COUNTIF(G12:J12,O12)>1,"Tie",INDEX($G$6:$J$6,MATCH(O12,G12:J12,0)))) -> Ferguson | Q12: =IF($S12>=2,MAX(G12:J12)/MIN(G12:J12)-1,"—") -> 0.1627907 | R12: =IF($S12>=2,(MAX(G12:J12)-MIN(G12:J12))*$F12,"—") -> 238.98 | S12: =COUNT(G12:J12) -> 3 | T12: =IF($S12<=1,IF($S12=1,"Single quote","—"),"Like-for-like") -> Like-for-like | U12: =IF(COUNT(W12:Z12)<2,"",IF(MAX(W12:Z12)=MIN(W12:Z12),"OK","Qty differs")) -> OK | W12: =IF(COUNTIFS('Quote Lines'!$P$3:$P$805,$A12&"|"&G$6&"|1",'Quote Lines'!$M$3:$M$805,"Y")=0,"",SUMIFS('Quote Lines'!$L$3:$L$805,'Quote Lines'!$P$3:$P$805,$A12&"|"&G$6&"|1",'Quote Lines'!$M$3:$M$805,"Y")) -> 1 | X12: =IF(COUNTIFS('Quote Lines'!$P$3:$P$805,$A12&"|"&H$6&"|1",'Quote Lines'!$M$3:$M$805,"Y")=0,"",SUMIFS('Quote Lines'!$L$3:$L$805,'Quote Lines'!$P$3:$P$805,$A12&"|"&H$6&"|1",'Quote Lines'!$M$3:$M$805,"Y")) -> 1 | Z12: =IF(COUNTIFS('Quote Lines'!$P$3:$P$805,$A12&"|"&J$6&"|1",'Quote Lines'!$M$3:$M$805,"Y")=0,"",SUMIFS('Quote Lines'!$L$3:$L$805,'Quote Lines'!$P$3:$P$805,$A12&"|"&J$6&"|1",'Quote Lines'!$M$3:$M$805,"Y")) -> 1 | AA12: =IF(ISNUMBER(G12),1+SUMPRODUCT(ISNUMBER($G12:$J12)*($G12:$J12<G12)),"") -> 1 | AB12: =IF(ISNUMBER(H12),1+SUMPRODUCT(ISNUMBER($G12:$J12)*($G12:$J12<H12)),"") -> 2 | AC12: =IF(ISNUMBER(I12),1+SUMPRODUCT(ISNUMBER($G12:$J12)*($G12:$J12<I12)),"") | AD12: =IF(ISNUMBER(J12),1+SUMPRODUCT(ISNUMBER($G12:$J12)*($G12:$J12<J12)),"") -> 3 | AE12: =IF(NOT(ISNUMBER(G12)),0,IF($S12<2,5,IF(AA12=1,1,IF(G12=MAX($G12:$J12),4,IF(AA12=2,2,3))))) -> 1 | AF12: =IF(NOT(ISNUMBER(H12)),0,IF($S12<2,5,IF(AB12=1,1,IF(H12=MAX($G12:$J12),4,IF(AB12=2,2,3))))) -> 2 | AG12: =IF(NOT(ISNUMBER(I12)),0,IF($S12<2,5,IF(AC12=1,1,IF(I12=MAX($G12:$J12),4,IF(AC12=2,2,3))))) -> 0 | AH12: =IF(NOT(ISNUMBER(J12)),0,IF($S12<2,5,IF(AD12=1,1,IF(J12=MAX($G12:$J12),4,IF(AD12=2,2,3))))) -> 4 | AI12: =IF($S12>=2,IF(ISNUMBER(G12),G12*$F12,MIN($G12:$J12)*$F12),0) -> 1468.02 | AJ12: =IF($S12>=2,IF(ISNUMBER(H12),H12*$F12,MIN($G12:$J12)*$F12),0) -> 1533.83 | AK12: =IF($S12>=2,IF(ISNUMBER(I12),I12*$F12,MIN($G12:$J12)*$F12),0) -> 1468.02 | AL12: =IF($S12>=2,IF(ISNUMBER(J12),J12*$F12,MIN($G12:$J12)*$F12),0) -> 1707 | AM12: =IF($S12>=2,$R12+ROW()/1000000,"") -> 238.98001 | AN12: =IF($S12>=2,MAX(G12:J12),"") -> 1707 | AO12: =IF($S12>=2,INDEX($G$6:$J$6,MATCH(MAX(G12:J12),G12:J12,0)),"") -> Scholzen | AP12: =IF($S12>=2,MIN(G12:J12)*$F12,0) -> 1468.02 | AQ12: =IF($S12>=2,INDEX($G$6:$J$6,MATCH(MIN(G12:J12),G12:J12,0)),"") -> Ferguson
A13: R006 | B13: Item 5 | C13: DI fittings | D13: 10" flanged tee | E13: EA | F13: 2 | G13: =IF(COUNTIF('Quote Lines'!$P$3:$P$805,$A13&"|"&G$6&"|1")=0,"—",SUMIFS('Quote Lines'!$O$3:$O$805,'Quote Lines'!$P$3:$P$805,$A13&"|"&G$6&"|1")/SUMIFS('Quote Lines'!$L$3:$L$805,'Quote Lines'!$P$3:$P$805,$A13&"|"&G$6&"|1")) -> 1012 | H13: =IF(COUNTIF('Quote Lines'!$P$3:$P$805,$A13&"|"&H$6&"|1")=0,"—",SUMIFS('Quote Lines'!$O$3:$O$805,'Quote Lines'!$P$3:$P$805,$A13&"|"&H$6&"|1")/SUMIFS('Quote Lines'!$L$3:$L$805,'Quote Lines'!$P$3:$P$805,$A13&"|"&H$6&"|1")) -> 1057.37 | I13: =IF(COUNTIF('Quote Lines'!$P$3:$P$805,$A13&"|"&I$6&"|1")=0,"—",SUMIFS('Quote Lines'!$O$3:$O$805,'Quote Lines'!$P$3:$P$805,$A13&"|"&I$6&"|1")/SUMIFS('Quote Lines'!$L$3:$L$805,'Quote Lines'!$P$3:$P$805,$A13&"|"&I$6&"|1")) -> 1148.05 | J13: =IF(COUNTIF('Quote Lines'!$P$3:$P$805,$A13&"|"&J$6&"|1")=0,"—",SUMIFS('Quote Lines'!$O$3:$O$805,'Quote Lines'!$P$3:$P$805,$A13&"|"&J$6&"|1")/SUMIFS('Quote Lines'!$L$3:$L$805,'Quote Lines'!$P$3:$P$805,$A13&"|"&J$6&"|1")) -> 1176.75 | K13: =IF(ISNUMBER(G13),G13*$F13,"—") -> 2024 | L13: =IF(ISNUMBER(H13),H13*$F13,"—") -> 2114.74 | M13: =IF(ISNUMBER(I13),I13*$F13,"—") -> 2296.1 | N13: =IF(ISNUMBER(J13),J13*$F13,"—") -> 2353.5 | O13: =IF($S13=0,"—",MIN(G13:J13)) -> 1012 | P13: =IF($S13=0,"—",IF(COUNTIF(G13:J13,O13)>1,"Tie",INDEX($G$6:$J$6,MATCH(O13,G13:J13,0)))) -> Ferguson | Q13: =IF($S13>=2,MAX(G13:J13)/MIN(G13:J13)-1,"—") -> 0.16279644 | R13: =IF($S13>=2,(MAX(G13:J13)-MIN(G13:J13))*$F13,"—") -> 329.5 | S13: =COUNT(G13:J13) -> 4 | T13: =IF($S13<=1,IF($S13=1,"Single quote","—"),"Like-for-like") -> Like-for-like | U13: =IF(COUNT(W13:Z13)<2,"",IF(MAX(W13:Z13)=MIN(W13:Z13),"OK","Qty differs")) -> OK | W13: =IF(COUNTIFS('Quote Lines'!$P$3:$P$805,$A13&"|"&G$6&"|1",'Quote Lines'!$M$3:$M$805,"Y")=0,"",SUMIFS('Quote Lines'!$L$3:$L$805,'Quote Lines'!$P$3:$P$805,$A13&"|"&G$6&"|1",'Quote Lines'!$M$3:$M$805,"Y")) -> 2 | X13: =IF(COUNTIFS('Quote Lines'!$P$3:$P$805,$A13&"|"&H$6&"|1",'Quote Lines'!$M$3:$M$805,"Y")=0,"",SUMIFS('Quote Lines'!$L$3:$L$805,'Quote Lines'!$P$3:$P$805,$A13&"|"&H$6&"|1",'Quote Lines'!$M$3:$M$805,"Y")) -> 2 | Y13: =IF(COUNTIFS('Quote Lines'!$P$3:$P$805,$A13&"|"&I$6&"|1",'Quote Lines'!$M$3:$M$805,"Y")=0,"",SUMIFS('Quote Lines'!$L$3:$L$805,'Quote Lines'!$P$3:$P$805,$A13&"|"&I$6&"|1",'Quote Lines'!$M$3:$M$805,"Y")) -> 2 | Z13: =IF(COUNTIFS('Quote Lines'!$P$3:$P$805,$A13&"|"&J$6&"|1",'Quote Lines'!$M$3:$M$805,"Y")=0,"",SUMIFS('Quote Lines'!$L$3:$L$805,'Quote Lines'!$P$3:$P$805,$A13&"|"&J$6&"|1",'Quote Lines'!$M$3:$M$805,"Y")) -> 2 | AA13: =IF(ISNUMBER(G13),1+SUMPRODUCT(ISNUMBER($G13:$J13)*($G13:$J13<G13)),"") -> 1 | AB13: =IF(ISNUMBER(H13),1+SUMPRODUCT(ISNUMBER($G13:$J13)*($G13:$J13<H13)),"") -> 2 | AC13: =IF(ISNUMBER(I13),1+SUMPRODUCT(ISNUMBER($G13:$J13)*($G13:$J13<I13)),"") -> 3 | AD13: =IF(ISNUMBER(J13),1+SUMPRODUCT(ISNUMBER($G13:$J13)*($G13:$J13<J13)),"") -> 4 | AE13: =IF(NOT(ISNUMBER(G13)),0,IF($S13<2,5,IF(AA13=1,1,IF(G13=MAX($G13:$J13),4,IF(AA13=2,2,3))))) -> 1 | AF13: =IF(NOT(ISNUMBER(H13)),0,IF($S13<2,5,IF(AB13=1,1,IF(H13=MAX($G13:$J13),4,IF(AB13=2,2,3))))) -> 2 | AG13: =IF(NOT(ISNUMBER(I13)),0,IF($S13<2,5,IF(AC13=1,1,IF(I13=MAX($G13:$J13),4,IF(AC13=2,2,3))))) -> 3 | AH13: =IF(NOT(ISNUMBER(J13)),0,IF($S13<2,5,IF(AD13=1,1,IF(J13=MAX($G13:$J13),4,IF(AD13=2,2,3))))) -> 4 | AI13: =IF($S13>=2,IF(ISNUMBER(G13),G13*$F13,MIN($G13:$J13)*$F13),0) -> 2024 | AJ13: =IF($S13>=2,IF(ISNUMBER(H13),H13*$F13,MIN($G13:$J13)*$F13),0) -> 2114.74 | AK13: =IF($S13>=2,IF(ISNUMBER(I13),I13*$F13,MIN($G13:$J13)*$F13),0) -> 2296.1 | AL13: =IF($S13>=2,IF(ISNUMBER(J13),J13*$F13,MIN($G13:$J13)*$F13),0) -> 2353.5 | AM13: =IF($S13>=2,$R13+ROW()/1000000,"") -> 329.50001 | AN13: =IF($S13>=2,MAX(G13:J13),"") -> 1176.75 | AO13: =IF($S13>=2,INDEX($G$6:$J$6,MATCH(MAX(G13:J13),G13:J13,0)),"") -> Scholzen | AP13: =IF($S13>=2,MIN(G13:J13)*$F13,0) -> 2024 | AQ13: =IF($S13>=2,INDEX($G$6:$J$6,MATCH(MIN(G13:J13),G13:J13,0)),"") -> Ferguson
A14: R007 | B14: Item 5 | C14: DI fittings | D14: 10" x 8" flanged tee | E14: EA | F14: 2 | G14: =IF(COUNTIF('Quote Lines'!$P$3:$P$805,$A14&"|"&G$6&"|1")=0,"—",SUMIFS('Quote Lines'!$O$3:$O$805,'Quote Lines'!$P$3:$P$805,$A14&"|"&G$6&"|1")/SUMIFS('Quote Lines'!$L$3:$L$805,'Quote Lines'!$P$3:$P$805,$A14&"|"&G$6&"|1")) -> 870.11 | H14: =IF(COUNTIF('Quote Lines'!$P$3:$P$805,$A14&"|"&H$6&"|1")=0,"—",SUMIFS('Quote Lines'!$O$3:$O$805,'Quote Lines'!$P$3:$P$805,$A14&"|"&H$6&"|1")/SUMIFS('Quote Lines'!$L$3:$L$805,'Quote Lines'!$P$3:$P$805,$A14&"|"&H$6&"|1")) -> 909.11 | I14: =IF(COUNTIF('Quote Lines'!$P$3:$P$805,$A14&"|"&I$6&"|1")=0,"—",SUMIFS('Quote Lines'!$O$3:$O$805,'Quote Lines'!$P$3:$P$805,$A14&"|"&I$6&"|1")/SUMIFS('Quote Lines'!$L$3:$L$805,'Quote Lines'!$P$3:$P$805,$A14&"|"&I$6&"|1")) -> 987.075 | J14: =IF(COUNTIF('Quote Lines'!$P$3:$P$805,$A14&"|"&J$6&"|1")=0,"—",SUMIFS('Quote Lines'!$O$3:$O$805,'Quote Lines'!$P$3:$P$805,$A14&"|"&J$6&"|1")/SUMIFS('Quote Lines'!$L$3:$L$805,'Quote Lines'!$P$3:$P$805,$A14&"|"&J$6&"|1")) -> 1011.75 | K14: =IF(ISNUMBER(G14),G14*$F14,"—") -> 1740.22 | L14: =IF(ISNUMBER(H14),H14*$F14,"—") -> 1818.22 | M14: =IF(ISNUMBER(I14),I14*$F14,"—") -> 1974.15 | N14: =IF(ISNUMBER(J14),J14*$F14,"—") -> 2023.5 | O14: =IF($S14=0,"—",MIN(G14:J14)) -> 870.11 | P14: =IF($S14=0,"—",IF(COUNTIF(G14:J14,O14)>1,"Tie",INDEX($G$6:$J$6,MATCH(O14,G14:J14,0)))) -> Ferguson | Q14: =IF($S14>=2,MAX(G14:J14)/MIN(G14:J14)-1,"—") -> 0.16278402 | R14: =IF($S14>=2,(MAX(G14:J14)-MIN(G14:J14))*$F14,"—") -> 283.28 | S14: =COUNT(G14:J14) -> 4 | T14: =IF($S14<=1,IF($S14=1,"Single quote","—"),"Like-for-like") -> Like-for-like | U14: =IF(COUNT(W14:Z14)<2,"",IF(MAX(W14:Z14)=MIN(W14:Z14),"OK","Qty differs")) -> OK | W14: =IF(COUNTIFS('Quote Lines'!$P$3:$P$805,$A14&"|"&G$6&"|1",'Quote Lines'!$M$3:$M$805,"Y")=0,"",SUMIFS('Quote Lines'!$L$3:$L$805,'Quote Lines'!$P$3:$P$805,$A14&"|"&G$6&"|1",'Quote Lines'!$M$3:$M$805,"Y")) -> 2 | X14: =IF(COUNTIFS('Quote Lines'!$P$3:$P$805,$A14&"|"&H$6&"|1",'Quote Lines'!$M$3:$M$805,"Y")=0,"",SUMIFS('Quote Lines'!$L$3:$L$805,'Quote Lines'!$P$3:$P$805,$A14&"|"&H$6&"|1",'Quote Lines'!$M$3:$M$805,"Y")) -> 2 | Y14: =IF(COUNTIFS('Quote Lines'!$P$3:$P$805,$A14&"|"&I$6&"|1",'Quote Lines'!$M$3:$M$805,"Y")=0,"",SUMIFS('Quote Lines'!$L$3:$L$805,'Quote Lines'!$P$3:$P$805,$A14&"|"&I$6&"|1",'Quote Lines'!$M$3:$M$805,"Y")) -> 2 | Z14: =IF(COUNTIFS('Quote Lines'!$P$3:$P$805,$A14&"|"&J$6&"|1",'Quote Lines'!$M$3:$M$805,"Y")=0,"",SUMIFS('Quote Lines'!$L$3:$L$805,'Quote Lines'!$P$3:$P$805,$A14&"|"&J$6&"|1",'Quote Lines'!$M$3:$M$805,"Y")) -> 2 | AA14: =IF(ISNUMBER(G14),1+SUMPRODUCT(ISNUMBER($G14:$J14)*($G14:$J14<G14)),"") -> 1 | AB14: =IF(ISNUMBER(H14),1+SUMPRODUCT(ISNUMBER($G14:$J14)*($G14:$J14<H14)),"") -> 2 | AC14: =IF(ISNUMBER(I14),1+SUMPRODUCT(ISNUMBER($G14:$J14)*($G14:$J14<I14)),"") -> 3 | AD14: =IF(ISNUMBER(J14),1+SUMPRODUCT(ISNUMBER($G14:$J14)*($G14:$J14<J14)),"") -> 4 | AE14: =IF(NOT(ISNUMBER(G14)),0,IF($S14<2,5,IF(AA14=1,1,IF(G14=MAX($G14:$J14),4,IF(AA14=2,2,3))))) -> 1 | AF14: =IF(NOT(ISNUMBER(H14)),0,IF($S14<2,5,IF(AB14=1,1,IF(H14=MAX($G14:$J14),4,IF(AB14=2,2,3))))) -> 2 | AG14: =IF(NOT(ISNUMBER(I14)),0,IF($S14<2,5,IF(AC14=1,1,IF(I14=MAX($G14:$J14),4,IF(AC14=2,2,3))))) -> 3 | AH14: =IF(NOT(ISNUMBER(J14)),0,IF($S14<2,5,IF(AD14=1,1,IF(J14=MAX($G14:$J14),4,IF(AD14=2,2,3))))) -> 4 | AI14: =IF($S14>=2,IF(ISNUMBER(G14),G14*$F14,MIN($G14:$J14)*$F14),0) -> 1740.22 | AJ14: =IF($S14>=2,IF(ISNUMBER(H14),H14*$F14,MIN($G14:$J14)*$F14),0) -> 1818.22 | AK14: =IF($S14>=2,IF(ISNUMBER(I14),I14*$F14,MIN($G14:$J14)*$F14),0) -> 1974.15 | AL14: =IF($S14>=2,IF(ISNUMBER(J14),J14*$F14,MIN($G14:$J14)*$F14),0) -> 2023.5 | AM14: =IF($S14>=2,$R14+ROW()/1000000,"") -> 283.28001 | AN14: =IF($S14>=2,MAX(G14:J14),"") -> 1011.75 | AO14: =IF($S14>=2,INDEX($G$6:$J$6,MATCH(MAX(G14:J14),G14:J14,0)),"") -> Scholzen | AP14: =IF($S14>=2,MIN(G14:J14)*$F14,0) -> 1740.22 | AQ14: =IF($S14>=2,INDEX($G$6:$J$6,MATCH(MIN(G14:J14),G14:J14,0)),"") -> Ferguson
A15: R008 | B15: Item 5 | C15: DI fittings | D15: 8" flanged 90° elbow | E15: EA | F15: 2 | G15: =IF(COUNTIF('Quote Lines'!$P$3:$P$805,$A15&"|"&G$6&"|1")=0,"—",SUMIFS('Quote Lines'!$O$3:$O$805,'Quote Lines'!$P$3:$P$805,$A15&"|"&G$6&"|1")/SUMIFS('Quote Lines'!$L$3:$L$805,'Quote Lines'!$P$3:$P$805,$A15&"|"&G$6&"|1")) -> 446.99 | H15: =IF(COUNTIF('Quote Lines'!$P$3:$P$805,$A15&"|"&H$6&"|1")=0,"—",SUMIFS('Quote Lines'!$O$3:$O$805,'Quote Lines'!$P$3:$P$805,$A15&"|"&H$6&"|1")/SUMIFS('Quote Lines'!$L$3:$L$805,'Quote Lines'!$P$3:$P$805,$A15&"|"&H$6&"|1")) -> 467.02 | I15: =IF(COUNTIF('Quote Lines'!$P$3:$P$805,$A15&"|"&I$6&"|1")=0,"—",SUMIFS('Quote Lines'!$O$3:$O$805,'Quote Lines'!$P$3:$P$805,$A15&"|"&I$6&"|1")/SUMIFS('Quote Lines'!$L$3:$L$805,'Quote Lines'!$P$3:$P$805,$A15&"|"&I$6&"|1")) -> 507.075 | J15: =IF(COUNTIF('Quote Lines'!$P$3:$P$805,$A15&"|"&J$6&"|1")=0,"—",SUMIFS('Quote Lines'!$O$3:$O$805,'Quote Lines'!$P$3:$P$805,$A15&"|"&J$6&"|1")/SUMIFS('Quote Lines'!$L$3:$L$805,'Quote Lines'!$P$3:$P$805,$A15&"|"&J$6&"|1")) -> 519.75 | K15: =IF(ISNUMBER(G15),G15*$F15,"—") -> 893.98 | L15: =IF(ISNUMBER(H15),H15*$F15,"—") -> 934.04 | M15: =IF(ISNUMBER(I15),I15*$F15,"—") -> 1014.15 | N15: =IF(ISNUMBER(J15),J15*$F15,"—") -> 1039.5 | O15: =IF($S15=0,"—",MIN(G15:J15)) -> 446.99 | P15: =IF($S15=0,"—",IF(COUNTIF(G15:J15,O15)>1,"Tie",INDEX($G$6:$J$6,MATCH(O15,G15:J15,0)))) -> Ferguson | Q15: =IF($S15>=2,MAX(G15:J15)/MIN(G15:J15)-1,"—") -> 0.16277769 | R15: =IF($S15>=2,(MAX(G15:J15)-MIN(G15:J15))*$F15,"—") -> 145.52 | S15: =COUNT(G15:J15) -> 4 | T15: =IF($S15<=1,IF($S15=1,"Single quote","—"),"Like-for-like") -> Like-for-like | U15: =IF(COUNT(W15:Z15)<2,"",IF(MAX(W15:Z15)=MIN(W15:Z15),"OK","Qty differs")) -> OK | W15: =IF(COUNTIFS('Quote Lines'!$P$3:$P$805,$A15&"|"&G$6&"|1",'Quote Lines'!$M$3:$M$805,"Y")=0,"",SUMIFS('Quote Lines'!$L$3:$L$805,'Quote Lines'!$P$3:$P$805,$A15&"|"&G$6&"|1",'Quote Lines'!$M$3:$M$805,"Y")) -> 2 | X15: =IF(COUNTIFS('Quote Lines'!$P$3:$P$805,$A15&"|"&H$6&"|1",'Quote Lines'!$M$3:$M$805,"Y")=0,"",SUMIFS('Quote Lines'!$L$3:$L$805,'Quote Lines'!$P$3:$P$805,$A15&"|"&H$6&"|1",'Quote Lines'!$M$3:$M$805,"Y")) -> 2 | Y15: =IF(COUNTIFS('Quote Lines'!$P$3:$P$805,$A15&"|"&I$6&"|1",'Quote Lines'!$M$3:$M$805,"Y")=0,"",SUMIFS('Quote Lines'!$L$3:$L$805,'Quote Lines'!$P$3:$P$805,$A15&"|"&I$6&"|1",'Quote Lines'!$M$3:$M$805,"Y")) -> 2 | Z15: =IF(COUNTIFS('Quote Lines'!$P$3:$P$805,$A15&"|"&J$6&"|1",'Quote Lines'!$M$3:$M$805,"Y")=0,"",SUMIFS('Quote Lines'!$L$3:$L$805,'Quote Lines'!$P$3:$P$805,$A15&"|"&J$6&"|1",'Quote Lines'!$M$3:$M$805,"Y")) -> 2 | AA15: =IF(ISNUMBER(G15),1+SUMPRODUCT(ISNUMBER($G15:$J15)*($G15:$J15<G15)),"") -> 1 | AB15: =IF(ISNUMBER(H15),1+SUMPRODUCT(ISNUMBER($G15:$J15)*($G15:$J15<H15)),"") -> 2 | AC15: =IF(ISNUMBER(I15),1+SUMPRODUCT(ISNUMBER($G15:$J15)*($G15:$J15<I15)),"") -> 3 | AD15: =IF(ISNUMBER(J15),1+SUMPRODUCT(ISNUMBER($G15:$J15)*($G15:$J15<J15)),"") -> 4 | AE15: =IF(NOT(ISNUMBER(G15)),0,IF($S15<2,5,IF(AA15=1,1,IF(G15=MAX($G15:$J15),4,IF(AA15=2,2,3))))) -> 1 | AF15: =IF(NOT(ISNUMBER(H15)),0,IF($S15<2,5,IF(AB15=1,1,IF(H15=MAX($G15:$J15),4,IF(AB15=2,2,3))))) -> 2 | AG15: =IF(NOT(ISNUMBER(I15)),0,IF($S15<2,5,IF(AC15=1,1,IF(I15=MAX($G15:$J15),4,IF(AC15=2,2,3))))) -> 3 | AH15: =IF(NOT(ISNUMBER(J15)),0,IF($S15<2,5,IF(AD15=1,1,IF(J15=MAX($G15:$J15),4,IF(AD15=2,2,3))))) -> 4 | AI15: =IF($S15>=2,IF(ISNUMBER(G15),G15*$F15,MIN($G15:$J15)*$F15),0) -> 893.98 | AJ15: =IF($S15>=2,IF(ISNUMBER(H15),H15*$F15,MIN($G15:$J15)*$F15),0) -> 934.04 | AK15: =IF($S15>=2,IF(ISNUMBER(I15),I15*$F15,MIN($G15:$J15)*$F15),0) -> 1014.15 | AL15: =IF($S15>=2,IF(ISNUMBER(J15),J15*$F15,MIN($G15:$J15)*$F15),0) -> 1039.5 | AM15: =IF($S15>=2,$R15+ROW()/1000000,"") -> 145.52002 | AN15: =IF($S15>=2,MAX(G15:J15),"") -> 519.75 | AO15: =IF($S15>=2,INDEX($G$6:$J$6,MATCH(MAX(G15:J15),G15:J15,0)),"") -> Scholzen | AP15: =IF($S15>=2,MIN(G15:J15)*$F15,0) -> 893.98 | AQ15: =IF($S15>=2,INDEX($G$6:$J$6,MATCH(MIN(G15:J15),G15:J15,0)),"") -> Ferguson
A16: R009 | B16: Item 5 | C16: DI fittings | D16: 12" MJ x flange 45° bend | E16: EA | F16: 1 | G16: =IF(COUNTIF('Quote Lines'!$P$3:$P$805,$A16&"|"&G$6&"|1")=0,"—",SUMIFS('Quote Lines'!$O$3:$O$805,'Quote Lines'!$P$3:$P$805,$A16&"|"&G$6&"|1")/SUMIFS('Quote Lines'!$L$3:$L$805,'Quote Lines'!$P$3:$P$805,$A16&"|"&G$6&"|1")) -> 728.21 | H16: — | I16: — | J16: — | K16: =IF(ISNUMBER(G16),G16*$F16,"—") -> 728.21 | L16: =IF(ISNUMBER(H16),H16*$F16,"—") -> — | M16: =IF(ISNUMBER(I16),I16*$F16,"—") -> — | N16: =IF(ISNUMBER(J16),J16*$F16,"—") -> — | O16: =IF($S16=0,"—",MIN(G16:J16)) -> 728.21 | P16: =IF($S16=0,"—",IF(COUNTIF(G16:J16,O16)>1,"Tie",INDEX($G$6:$J$6,MATCH(O16,G16:J16,0)))) -> Ferguson | Q16: =IF($S16>=2,MAX(G16:J16)/MIN(G16:J16)-1,"—") -> — | R16: =IF($S16>=2,(MAX(G16:J16)-MIN(G16:J16))*$F16,"—") -> — | S16: =COUNT(G16:J16) -> 1 | T16: =IF($S16<=1,IF($S16=1,"Single quote","—"),"Like-for-like") -> Single quote | U16: =IF(COUNT(W16:Z16)<2,"",IF(MAX(W16:Z16)=MIN(W16:Z16),"OK","Qty differs")) | V16: Only Ferguson priced the MJ x flange end configuration. | W16: =IF(COUNTIFS('Quote Lines'!$P$3:$P$805,$A16&"|"&G$6&"|1",'Quote Lines'!$M$3:$M$805,"Y")=0,"",SUMIFS('Quote Lines'!$L$3:$L$805,'Quote Lines'!$P$3:$P$805,$A16&"|"&G$6&"|1",'Quote Lines'!$M$3:$M$805,"Y")) -> 1 | AA16: =IF(ISNUMBER(G16),1+SUMPRODUCT(ISNUMBER($G16:$J16)*($G16:$J16<G16)),"") -> 1 | AB16: =IF(ISNUMBER(H16),1+SUMPRODUCT(ISNUMBER($G16:$J16)*($G16:$J16<H16)),"") | AC16: =IF(ISNUMBER(I16),1+SUMPRODUCT(ISNUMBER($G16:$J16)*($G16:$J16<I16)),"") | AD16: =IF(ISNUMBER(J16),1+SUMPRODUCT(ISNUMBER($G16:$J16)*($G16:$J16<J16)),"") | AE16: =IF(NOT(ISNUMBER(G16)),0,IF($S16<2,5,IF(AA16=1,1,IF(G16=MAX($G16:$J16),4,IF(AA16=2,2,3))))) -> 5 | AF16: =IF(NOT(ISNUMBER(H16)),0,IF($S16<2,5,IF(AB16=1,1,IF(H16=MAX($G16:$J16),4,IF(AB16=2,2,3))))) -> 0 | AG16: =IF(NOT(ISNUMBER(I16)),0,IF($S16<2,5,IF(AC16=1,1,IF(I16=MAX($G16:$J16),4,IF(AC16=2,2,3))))) -> 0 | AH16: =IF(NOT(ISNUMBER(J16)),0,IF($S16<2,5,IF(AD16=1,1,IF(J16=MAX($G16:$J16),4,IF(AD16=2,2,3))))) -> 0 | AI16: =IF($S16>=2,IF(ISNUMBER(G16),G16*$F16,MIN($G16:$J16)*$F16),0) -> 0 | AJ16: =IF($S16>=2,IF(ISNUMBER(H16),H16*$F16,MIN($G16:$J16)*$F16),0) -> 0 | AK16: =IF($S16>=2,IF(ISNUMBER(I16),I16*$F16,MIN($G16:$J16)*$F16),0) -> 0 | AL16: =IF($S16>=2,IF(ISNUMBER(J16),J16*$F16,MIN($G16:$J16)*$F16),0) -> 0 | AM16: =IF($S16>=2,$R16+ROW()/1000000,"") | AN16: =IF($S16>=2,MAX(G16:J16),"") | AO16: =IF($S16>=2,INDEX($G$6:$J$6,MATCH(MAX(G16:J16),G16:J16,0)),"") | AP16: =IF($S16>=2,MIN(G16:J16)*$F16,0) -> 0 | AQ16: =IF($S16>=2,INDEX($G$6:$J$6,MATCH(MIN(G16:J16),G16:J16,0)),"")
A17: R010 | B17: Item 5 | C17: DI fittings | D17: 12" MJ x flange 22-1/2° bend | E17: EA | F17: 1 | G17: =IF(COUNTIF('Quote Lines'!$P$3:$P$805,$A17&"|"&G$6&"|1")=0,"—",SUMIFS('Quote Lines'!$O$3:$O$805,'Quote Lines'!$P$3:$P$805,$A17&"|"&G$6&"|1")/SUMIFS('Quote Lines'!$L$3:$L$805,'Quote Lines'!$P$3:$P$805,$A17&"|"&G$6&"|1")) -> 636.61 | H17: =IF(COUNTIF('Quote Lines'!$P$3:$P$805,$A17&"|"&H$6&"|1")=0,"—",SUMIFS('Quote Lines'!$O$3:$O$805,'Quote Lines'!$P$3:$P$805,$A17&"|"&H$6&"|1")/SUMIFS('Quote Lines'!$L$3:$L$805,'Quote Lines'!$P$3:$P$805,$A17&"|"&H$6&"|1")) -> 665.15 | I17: — | J17: — | K17: =IF(ISNUMBER(G17),G17*$F17,"—") -> 636.61 | L17: =IF(ISNUMBER(H17),H17*$F17,"—") -> 665.15 | M17: =IF(ISNUMBER(I17),I17*$F17,"—") -> — | N17: =IF(ISNUMBER(J17),J17*$F17,"—") -> — | O17: =IF($S17=0,"—",MIN(G17:J17)) -> 636.61 | P17: =IF($S17=0,"—",IF(COUNTIF(G17:J17,O17)>1,"Tie",INDEX($G$6:$J$6,MATCH(O17,G17:J17,0)))) -> Ferguson | Q17: =IF($S17>=2,MAX(G17:J17)/MIN(G17:J17)-1,"—") -> 0.044831215 | R17: =IF($S17>=2,(MAX(G17:J17)-MIN(G17:J17))*$F17,"—") -> 28.54 | S17: =COUNT(G17:J17) -> 2 | T17: =IF($S17<=1,IF($S17=1,"Single quote","—"),"Like-for-like") -> Like-for-like | U17: =IF(COUNT(W17:Z17)<2,"",IF(MAX(W17:Z17)=MIN(W17:Z17),"OK","Qty differs")) -> OK | W17: =IF(COUNTIFS('Quote Lines'!$P$3:$P$805,$A17&"|"&G$6&"|1",'Quote Lines'!$M$3:$M$805,"Y")=0,"",SUMIFS('Quote Lines'!$L$3:$L$805,'Quote Lines'!$P$3:$P$805,$A17&"|"&G$6&"|1",'Quote Lines'!$M$3:$M$805,"Y")) -> 1 | X17: =IF(COUNTIFS('Quote Lines'!$P$3:$P$805,$A17&"|"&H$6&"|1",'Quote Lines'!$M$3:$M$805,"Y")=0,"",SUMIFS('Quote Lines'!$L$3:$L$805,'Quote Lines'!$P$3:$P$805,$A17&"|"&H$6&"|1",'Quote Lines'!$M$3:$M$805,"Y")) -> 1 | AA17: =IF(ISNUMBER(G17),1+SUMPRODUCT(ISNUMBER($G17:$J17)*($G17:$J17<G17)),"") -> 1 | AB17: =IF(ISNUMBER(H17),1+SUMPRODUCT(ISNUMBER($G17:$J17)*($G17:$J17<H17)),"") -> 2 | AC17: =IF(ISNUMBER(I17),1+SUMPRODUCT(ISNUMBER($G17:$J17)*($G17:$J17<I17)),"") | AD17: =IF(ISNUMBER(J17),1+SUMPRODUCT(ISNUMBER($G17:$J17)*($G17:$J17<J17)),"") | AE17: =IF(NOT(ISNUMBER(G17)),0,IF($S17<2,5,IF(AA17=1,1,IF(G17=MAX($G17:$J17),4,IF(AA17=2,2,3))))) -> 1 | AF17: =IF(NOT(ISNUMBER(H17)),0,IF($S17<2,5,IF(AB17=1,1,IF(H17=MAX($G17:$J17),4,IF(AB17=2,2,3))))) -> 4 | AG17: =IF(NOT(ISNUMBER(I17)),0,IF($S17<2,5,IF(AC17=1,1,IF(I17=MAX($G17:$J17),4,IF(AC17=2,2,3))))) -> 0 | AH17: =IF(NOT(ISNUMBER(J17)),0,IF($S17<2,5,IF(AD17=1,1,IF(J17=MAX($G17:$J17),4,IF(AD17=2,2,3))))) -> 0 | AI17: =IF($S17>=2,IF(ISNUMBER(G17),G17*$F17,MIN($G17:$J17)*$F17),0) -> 636.61 | AJ17: =IF($S17>=2,IF(ISNUMBER(H17),H17*$F17,MIN($G17:$J17)*$F17),0) -> 665.15 | AK17: =IF($S17>=2,IF(ISNUMBER(I17),I17*$F17,MIN($G17:$J17)*$F17),0) -> 636.61 | AL17: =IF($S17>=2,IF(ISNUMBER(J17),J17*$F17,MIN($G17:$J17)*$F17),0) -> 636.61 | AM17: =IF($S17>=2,$R17+ROW()/1000000,"") -> 28.540017 | AN17: =IF($S17>=2,MAX(G17:J17),"") -> 665.15 | AO17: =IF($S17>=2,INDEX($G$6:$J$6,MATCH(MAX(G17:J17),G17:J17,0)),"") -> HD Fowler | AP17: =IF($S17>=2,MIN(G17:J17)*$F17,0) -> 636.61 | AQ17: =IF($S17>=2,INDEX($G$6:$J$6,MATCH(MIN(G17:J17),G17:J17,0)),"") -> Ferguson
A18: R011 | B18: Item 5 | C18: DI fittings | D18: 12" MJ 45° bend (MJ x MJ) | E18: EA | F18: 1 | G18: — | H18: =IF(COUNTIF('Quote Lines'!$P$3:$P$805,$A18&"|"&H$6&"|1")=0,"—",SUMIFS('Quote Lines'!$O$3:$O$805,'Quote Lines'!$P$3:$P$805,$A18&"|"&H$6&"|1")/SUMIFS('Quote Lines'!$L$3:$L$805,'Quote Lines'!$P$3:$P$805,$A18&"|"&H$6&"|1")) -> 418.5 | I18: — | J18: =IF(COUNTIF('Quote Lines'!$P$3:$P$805,$A18&"|"&J$6&"|1")=0,"—",SUMIFS('Quote Lines'!$O$3:$O$805,'Quote Lines'!$P$3:$P$805,$A18&"|"&J$6&"|1")/SUMIFS('Quote Lines'!$L$3:$L$805,'Quote Lines'!$P$3:$P$805,$A18&"|"&J$6&"|1")) -> 465.75 | K18: =IF(ISNUMBER(G18),G18*$F18,"—") -> — | L18: =IF(ISNUMBER(H18),H18*$F18,"—") -> 418.5 | M18: =IF(ISNUMBER(I18),I18*$F18,"—") -> — | N18: =IF(ISNUMBER(J18),J18*$F18,"—") -> 465.75 | O18: =IF($S18=0,"—",MIN(G18:J18)) -> 418.5 | P18: =IF($S18=0,"—",IF(COUNTIF(G18:J18,O18)>1,"Tie",INDEX($G$6:$J$6,MATCH(O18,G18:J18,0)))) -> HD Fowler | Q18: =IF($S18>=2,MAX(G18:J18)/MIN(G18:J18)-1,"—") -> 0.11290323 | R18: =IF($S18>=2,(MAX(G18:J18)-MIN(G18:J18))*$F18,"—") -> 47.25 | S18: =COUNT(G18:J18) -> 2 | T18: =IF($S18<=1,IF($S18=1,"Single quote","—"),"Like-for-like") -> Like-for-like | U18: =IF(COUNT(W18:Z18)<2,"",IF(MAX(W18:Z18)=MIN(W18:Z18),"OK","Qty differs")) -> OK | X18: =IF(COUNTIFS('Quote Lines'!$P$3:$P$805,$A18&"|"&H$6&"|1",'Quote Lines'!$M$3:$M$805,"Y")=0,"",SUMIFS('Quote Lines'!$L$3:$L$805,'Quote Lines'!$P$3:$P$805,$A18&"|"&H$6&"|1",'Quote Lines'!$M$3:$M$805,"Y")) -> 1 | Z18: =IF(COUNTIFS('Quote Lines'!$P$3:$P$805,$A18&"|"&J$6&"|1",'Quote Lines'!$M$3:$M$805,"Y")=0,"",SUMIFS('Quote Lines'!$L$3:$L$805,'Quote Lines'!$P$3:$P$805,$A18&"|"&J$6&"|1",'Quote Lines'!$M$3:$M$805,"Y")) -> 1 | AA18: =IF(ISNUMBER(G18),1+SUMPRODUCT(ISNUMBER($G18:$J18)*($G18:$J18<G18)),"") | AB18: =IF(ISNUMBER(H18),1+SUMPRODUCT(ISNUMBER($G18:$J18)*($G18:$J18<H18)),"") -> 1 | AC18: =IF(ISNUMBER(I18),1+SUMPRODUCT(ISNUMBER($G18:$J18)*($G18:$J18<I18)),"") | AD18: =IF(ISNUMBER(J18),1+SUMPRODUCT(ISNUMBER($G18:$J18)*($G18:$J18<J18)),"") -> 2 | AE18: =IF(NOT(ISNUMBER(G18)),0,IF($S18<2,5,IF(AA18=1,1,IF(G18=MAX($G18:$J18),4,IF(AA18=2,2,3))))) -> 0 | AF18: =IF(NOT(ISNUMBER(H18)),0,IF($S18<2,5,IF(AB18=1,1,IF(H18=MAX($G18:$J18),4,IF(AB18=2,2,3))))) -> 1 | AG18: =IF(NOT(ISNUMBER(I18)),0,IF($S18<2,5,IF(AC18=1,1,IF(I18=MAX($G18:$J18),4,IF(AC18=2,2,3))))) -> 0 | AH18: =IF(NOT(ISNUMBER(J18)),0,IF($S18<2,5,IF(AD18=1,1,IF(J18=MAX($G18:$J18),4,IF(AD18=2,2,3))))) -> 4 | AI18: =IF($S18>=2,IF(ISNUMBER(G18),G18*$F18,MIN($G18:$J18)*$F18),0) -> 418.5 | AJ18: =IF($S18>=2,IF(ISNUMBER(H18),H18*$F18,MIN($G18:$J18)*$F18),0) -> 418.5 | AK18: =IF($S18>=2,IF(ISNUMBER(I18),I18*$F18,MIN($G18:$J18)*$F18),0) -> 418.5 | AL18: =IF($S18>=2,IF(ISNUMBER(J18),J18*$F18,MIN($G18:$J18)*$F18),0) -> 465.75 | AM18: =IF($S18>=2,$R18+ROW()/1000000,"") -> 47.250018 | AN18: =IF($S18>=2,MAX(G18:J18),"") -> 465.75 | AO18: =IF($S18>=2,INDEX($G$6:$J$6,MATCH(MAX(G18:J18),G18:J18,0)),"") -> Scholzen | AP18: =IF($S18>=2,MIN(G18:J18)*$F18,0) -> 418.5 | AQ18: =IF($S18>=2,INDEX($G$6:$J$6,MATCH(MIN(G18:J18),G18:J18,0)),"") -> HD Fowler
A19: R012 | B19: Item 5 | C19: DI fittings | D19: 12" MJ 22-1/2° bend (MJ x MJ) | E19: EA | F19: 1 | G19: — | H19: — | I19: — | J19: =IF(COUNTIF('Quote Lines'!$P$3:$P$805,$A19&"|"&J$6&"|1")=0,"—",SUMIFS('Quote Lines'!$O$3:$O$805,'Quote Lines'!$P$3:$P$805,$A19&"|"&J$6&"|1")/SUMIFS('Quote Lines'!$L$3:$L$805,'Quote Lines'!$P$3:$P$805,$A19&"|"&J$6&"|1")) -> 406.5 | K19: =IF(ISNUMBER(G19),G19*$F19,"—") -> — | L19: =IF(ISNUMBER(H19),H19*$F19,"—") -> — | M19: =IF(ISNUMBER(I19),I19*$F19,"—") -> — | N19: =IF(ISNUMBER(J19),J19*$F19,"—") -> 406.5 | O19: =IF($S19=0,"—",MIN(G19:J19)) -> 406.5 | P19: =IF($S19=0,"—",IF(COUNTIF(G19:J19,O19)>1,"Tie",INDEX($G$6:$J$6,MATCH(O19,G19:J19,0)))) -> Scholzen | Q19: =IF($S19>=2,MAX(G19:J19)/MIN(G19:J19)-1,"—") -> — | R19: =IF($S19>=2,(MAX(G19:J19)-MIN(G19:J19))*$F19,"—") -> — | S19: =COUNT(G19:J19) -> 1 | T19: =IF($S19<=1,IF($S19=1,"Single quote","—"),"Like-for-like") -> Single quote | U19: =IF(COUNT(W19:Z19)<2,"",IF(MAX(W19:Z19)=MIN(W19:Z19),"OK","Qty differs")) | Z19: =IF(COUNTIFS('Quote Lines'!$P$3:$P$805,$A19&"|"&J$6&"|1",'Quote Lines'!$M$3:$M$805,"Y")=0,"",SUMIFS('Quote Lines'!$L$3:$L$805,'Quote Lines'!$P$3:$P$805,$A19&"|"&J$6&"|1",'Quote Lines'!$M$3:$M$805,"Y")) -> 1 | AA19: =IF(ISNUMBER(G19),1+SUMPRODUCT(ISNUMBER($G19:$J19)*($G19:$J19<G19)),"") | AB19: =IF(ISNUMBER(H19),1+SUMPRODUCT(ISNUMBER($G19:$J19)*($G19:$J19<H19)),"") | AC19: =IF(ISNUMBER(I19),1+SUMPRODUCT(ISNUMBER($G19:$J19)*($G19:$J19<I19)),"") | AD19: =IF(ISNUMBER(J19),1+SUMPRODUCT(ISNUMBER($G19:$J19)*($G19:$J19<J19)),"") -> 1 | AE19: =IF(NOT(ISNUMBER(G19)),0,IF($S19<2,5,IF(AA19=1,1,IF(G19=MAX($G19:$J19),4,IF(AA19=2,2,3))))) -> 0 | AF19: =IF(NOT(ISNUMBER(H19)),0,IF($S19<2,5,IF(AB19=1,1,IF(H19=MAX($G19:$J19),4,IF(AB19=2,2,3))))) -> 0 | AG19: =IF(NOT(ISNUMBER(I19)),0,IF($S19<2,5,IF(AC19=1,1,IF(I19=MAX($G19:$J19),4,IF(AC19=2,2,3))))) -> 0 | AH19: =IF(NOT(ISNUMBER(J19)),0,IF($S19<2,5,IF(AD19=1,1,IF(J19=MAX($G19:$J19),4,IF(AD19=2,2,3))))) -> 5 | AI19: =IF($S19>=2,IF(ISNUMBER(G19),G19*$F19,MIN($G19:$J19)*$F19),0) -> 0 | AJ19: =IF($S19>=2,IF(ISNUMBER(H19),H19*$F19,MIN($G19:$J19)*$F19),0) -> 0 | AK19: =IF($S19>=2,IF(ISNUMBER(I19),I19*$F19,MIN($G19:$J19)*$F19),0) -> 0 | AL19: =IF($S19>=2,IF(ISNUMBER(J19),J19*$F19,MIN($G19:$J19)*$F19),0) -> 0 | AM19: =IF($S19>=2,$R19+ROW()/1000000,"") | AN19: =IF($S19>=2,MAX(G19:J19),"") | AO19: =IF($S19>=2,INDEX($G$6:$J$6,MATCH(MAX(G19:J19),G19:J19,0)),"") | AP19: =IF($S19>=2,MIN(G19:J19)*$F19,0) -> 0 | AQ19: =IF($S19>=2,INDEX($G$6:$J$6,MATCH(MIN(G19:J19),G19:J19,0)),"")
A20: R013 | B20: Item 5 | C20: DI fittings | D20: 12" MJ x flange adapter | E20: EA | F20: 2 | G20: =IF(COUNTIF('Quote Lines'!$P$3:$P$805,$A20&"|"&G$6&"|1")=0,"—",SUMIFS('Quote Lines'!$O$3:$O$805,'Quote Lines'!$P$3:$P$805,$A20&"|"&G$6&"|1")/SUMIFS('Quote Lines'!$L$3:$L$805,'Quote Lines'!$P$3:$P$805,$A20&"|"&G$6&"|1")) -> 419.9 | H20: — | I20: — | J20: =IF(COUNTIF('Quote Lines'!$P$3:$P$805,$A20&"|"&J$6&"|1")=0,"—",SUMIFS('Quote Lines'!$O$3:$O$805,'Quote Lines'!$P$3:$P$805,$A20&"|"&J$6&"|1")/SUMIFS('Quote Lines'!$L$3:$L$805,'Quote Lines'!$P$3:$P$805,$A20&"|"&J$6&"|1")) -> 488.25 | K20: =IF(ISNUMBER(G20),G20*$F20,"—") -> 839.8 | L20: =IF(ISNUMBER(H20),H20*$F20,"—") -> — | M20: =IF(ISNUMBER(I20),I20*$F20,"—") -> — | N20: =IF(ISNUMBER(J20),J20*$F20,"—") -> 976.5 | O20: =IF($S20=0,"—",MIN(G20:J20)) -> 419.9 | P20: =IF($S20=0,"—",IF(COUNTIF(G20:J20,O20)>1,"Tie",INDEX($G$6:$J$6,MATCH(O20,G20:J20,0)))) -> Ferguson | Q20: =IF($S20>=2,MAX(G20:J20)/MIN(G20:J20)-1,"—") -> 0.16277685 | R20: =IF($S20>=2,(MAX(G20:J20)-MIN(G20:J20))*$F20,"—") -> 136.7 | S20: =COUNT(G20:J20) -> 2 | T20: =IF($S20<=1,IF($S20=1,"Single quote","—"),"Like-for-like") -> Like-for-like | U20: =IF(COUNT(W20:Z20)<2,"",IF(MAX(W20:Z20)=MIN(W20:Z20),"OK","Qty differs")) -> Qty differs | W20: =IF(COUNTIFS('Quote Lines'!$P$3:$P$805,$A20&"|"&G$6&"|1",'Quote Lines'!$M$3:$M$805,"Y")=0,"",SUMIFS('Quote Lines'!$L$3:$L$805,'Quote Lines'!$P$3:$P$805,$A20&"|"&G$6&"|1",'Quote Lines'!$M$3:$M$805,"Y")) -> 1 | Z20: =IF(COUNTIFS('Quote Lines'!$P$3:$P$805,$A20&"|"&J$6&"|1",'Quote Lines'!$M$3:$M$805,"Y")=0,"",SUMIFS('Quote Lines'!$L$3:$L$805,'Quote Lines'!$P$3:$P$805,$A20&"|"&J$6&"|1",'Quote Lines'!$M$3:$M$805,"Y")) -> 2 | AA20: =IF(ISNUMBER(G20),1+SUMPRODUCT(ISNUMBER($G20:$J20)*($G20:$J20<G20)),"") -> 1 | AB20: =IF(ISNUMBER(H20),1+SUMPRODUCT(ISNUMBER($G20:$J20)*($G20:$J20<H20)),"") | AC20: =IF(ISNUMBER(I20),1+SUMPRODUCT(ISNUMBER($G20:$J20)*($G20:$J20<I20)),"") | AD20: =IF(ISNUMBER(J20),1+SUMPRODUCT(ISNUMBER($G20:$J20)*($G20:$J20<J20)),"") -> 2 | AE20: =IF(NOT(ISNUMBER(G20)),0,IF($S20<2,5,IF(AA20=1,1,IF(G20=MAX($G20:$J20),4,IF(AA20=2,2,3))))) -> 1 | AF20: =IF(NOT(ISNUMBER(H20)),0,IF($S20<2,5,IF(AB20=1,1,IF(H20=MAX($G20:$J20),4,IF(AB20=2,2,3))))) -> 0 | AG20: =IF(NOT(ISNUMBER(I20)),0,IF($S20<2,5,IF(AC20=1,1,IF(I20=MAX($G20:$J20),4,IF(AC20=2,2,3))))) -> 0 | AH20: =IF(NOT(ISNUMBER(J20)),0,IF($S20<2,5,IF(AD20=1,1,IF(J20=MAX($G20:$J20),4,IF(AD20=2,2,3))))) -> 4 | AI20: =IF($S20>=2,IF(ISNUMBER(G20),G20*$F20,MIN($G20:$J20)*$F20),0) -> 839.8 | AJ20: =IF($S20>=2,IF(ISNUMBER(H20),H20*$F20,MIN($G20:$J20)*$F20),0) -> 839.8 | AK20: =IF($S20>=2,IF(ISNUMBER(I20),I20*$F20,MIN($G20:$J20)*$F20),0) -> 839.8 | AL20: =IF($S20>=2,IF(ISNUMBER(J20),J20*$F20,MIN($G20:$J20)*$F20),0) -> 976.5 | AM20: =IF($S20>=2,$R20+ROW()/1000000,"") -> 136.70002 | AN20: =IF($S20>=2,MAX(G20:J20),"") -> 488.25 | AO20: =IF($S20>=2,INDEX($G$6:$J$6,MATCH(MAX(G20:J20),G20:J20,0)),"") -> Scholzen | AP20: =IF($S20>=2,MIN(G20:J20)*$F20,0) -> 839.8 | AQ20: =IF($S20>=2,INDEX($G$6:$J$6,MATCH(MIN(G20:J20),G20:J20,0)),"") -> Ferguson
A21: R014 | B21: Item 5 | C21: DI fittings | D21: 12" MJ long sleeve | E21: EA | F21: 2 | G21: =IF(COUNTIF('Quote Lines'!$P$3:$P$805,$A21&"|"&G$6&"|1")=0,"—",SUMIFS('Quote Lines'!$O$3:$O$805,'Quote Lines'!$P$3:$P$805,$A21&"|"&G$6&"|1")/SUMIFS('Quote Lines'!$L$3:$L$805,'Quote Lines'!$P$3:$P$805,$A21&"|"&G$6&"|1")) -> 368.94 | H21: =IF(COUNTIF('Quote Lines'!$P$3:$P$805,$A21&"|"&H$6&"|1")=0,"—",SUMIFS('Quote Lines'!$O$3:$O$805,'Quote Lines'!$P$3:$P$805,$A21&"|"&H$6&"|1")/SUMIFS('Quote Lines'!$L$3:$L$805,'Quote Lines'!$P$3:$P$805,$A21&"|"&H$6&"|1")) -> 385.48 | I21: =IF(COUNTIF('Quote Lines'!$P$3:$P$805,$A21&"|"&I$6&"|1")=0,"—",SUMIFS('Quote Lines'!$O$3:$O$805,'Quote Lines'!$P$3:$P$805,$A21&"|"&I$6&"|1")/SUMIFS('Quote Lines'!$L$3:$L$805,'Quote Lines'!$P$3:$P$805,$A21&"|"&I$6&"|1")) -> 418.54 | J21: =IF(COUNTIF('Quote Lines'!$P$3:$P$805,$A21&"|"&J$6&"|1")=0,"—",SUMIFS('Quote Lines'!$O$3:$O$805,'Quote Lines'!$P$3:$P$805,$A21&"|"&J$6&"|1")/SUMIFS('Quote Lines'!$L$3:$L$805,'Quote Lines'!$P$3:$P$805,$A21&"|"&J$6&"|1")) -> 429 | K21: =IF(ISNUMBER(G21),G21*$F21,"—") -> 737.88 | L21: =IF(ISNUMBER(H21),H21*$F21,"—") -> 770.96 | M21: =IF(ISNUMBER(I21),I21*$F21,"—") -> 837.08 | N21: =IF(ISNUMBER(J21),J21*$F21,"—") -> 858 | O21: =IF($S21=0,"—",MIN(G21:J21)) -> 368.94 | P21: =IF($S21=0,"—",IF(COUNTIF(G21:J21,O21)>1,"Tie",INDEX($G$6:$J$6,MATCH(O21,G21:J21,0)))) -> Ferguson | Q21: =IF($S21>=2,MAX(G21:J21)/MIN(G21:J21)-1,"—") -> 0.1627907 | R21: =IF($S21>=2,(MAX(G21:J21)-MIN(G21:J21))*$F21,"—") -> 120.12 | S21: =COUNT(G21:J21) -> 4 | T21: =IF($S21<=1,IF($S21=1,"Single quote","—"),"Like-for-like") -> Like-for-like | U21: =IF(COUNT(W21:Z21)<2,"",IF(MAX(W21:Z21)=MIN(W21:Z21),"OK","Qty differs")) -> Qty differs | W21: =IF(COUNTIFS('Quote Lines'!$P$3:$P$805,$A21&"|"&G$6&"|1",'Quote Lines'!$M$3:$M$805,"Y")=0,"",SUMIFS('Quote Lines'!$L$3:$L$805,'Quote Lines'!$P$3:$P$805,$A21&"|"&G$6&"|1",'Quote Lines'!$M$3:$M$805,"Y")) -> 3 | X21: =IF(COUNTIFS('Quote Lines'!$P$3:$P$805,$A21&"|"&H$6&"|1",'Quote Lines'!$M$3:$M$805,"Y")=0,"",SUMIFS('Quote Lines'!$L$3:$L$805,'Quote Lines'!$P$3:$P$805,$A21&"|"&H$6&"|1",'Quote Lines'!$M$3:$M$805,"Y")) -> 2 | Y21: =IF(COUNTIFS('Quote Lines'!$P$3:$P$805,$A21&"|"&I$6&"|1",'Quote Lines'!$M$3:$M$805,"Y")=0,"",SUMIFS('Quote Lines'!$L$3:$L$805,'Quote Lines'!$P$3:$P$805,$A21&"|"&I$6&"|1",'Quote Lines'!$M$3:$M$805,"Y")) -> 1 | Z21: =IF(COUNTIFS('Quote Lines'!$P$3:$P$805,$A21&"|"&J$6&"|1",'Quote Lines'!$M$3:$M$805,"Y")=0,"",SUMIFS('Quote Lines'!$L$3:$L$805,'Quote Lines'!$P$3:$P$805,$A21&"|"&J$6&"|1",'Quote Lines'!$M$3:$M$805,"Y")) -> 2 | AA21: =IF(ISNUMBER(G21),1+SUMPRODUCT(ISNUMBER($G21:$J21)*($G21:$J21<G21)),"") -> 1 | AB21: =IF(ISNUMBER(H21),1+SUMPRODUCT(ISNUMBER($G21:$J21)*($G21:$J21<H21)),"") -> 2 | AC21: =IF(ISNUMBER(I21),1+SUMPRODUCT(ISNUMBER($G21:$J21)*($G21:$J21<I21)),"") -> 3 | AD21: =IF(ISNUMBER(J21),1+SUMPRODUCT(ISNUMBER($G21:$J21)*($G21:$J21<J21)),"") -> 4 | AE21: =IF(NOT(ISNUMBER(G21)),0,IF($S21<2,5,IF(AA21=1,1,IF(G21=MAX($G21:$J21),4,IF(AA21=2,2,3))))) -> 1 | AF21: =IF(NOT(ISNUMBER(H21)),0,IF($S21<2,5,IF(AB21=1,1,IF(H21=MAX($G21:$J21),4,IF(AB21=2,2,3))))) -> 2 | AG21: =IF(NOT(ISNUMBER(I21)),0,IF($S21<2,5,IF(AC21=1,1,IF(I21=MAX($G21:$J21),4,IF(AC21=2,2,3))))) -> 3 | AH21: =IF(NOT(ISNUMBER(J21)),0,IF($S21<2,5,IF(AD21=1,1,IF(J21=MAX($G21:$J21),4,IF(AD21=2,2,3))))) -> 4 | AI21: =IF($S21>=2,IF(ISNUMBER(G21),G21*$F21,MIN($G21:$J21)*$F21),0) -> 737.88 | AJ21: =IF($S21>=2,IF(ISNUMBER(H21),H21*$F21,MIN($G21:$J21)*$F21),0) -> 770.96 | AK21: =IF($S21>=2,IF(ISNUMBER(I21),I21*$F21,MIN($G21:$J21)*$F21),0) -> 837.08 | AL21: =IF($S21>=2,IF(ISNUMBER(J21),J21*$F21,MIN($G21:$J21)*$F21),0) -> 858 | AM21: =IF($S21>=2,$R21+ROW()/1000000,"") -> 120.12002 | AN21: =IF($S21>=2,MAX(G21:J21),"") -> 429 | AO21: =IF($S21>=2,INDEX($G$6:$J$6,MATCH(MAX(G21:J21),G21:J21,0)),"") -> Scholzen | AP21: =IF($S21>=2,MIN(G21:J21)*$F21,0) -> 737.88 | AQ21: =IF($S21>=2,INDEX($G$6:$J$6,MATCH(MIN(G21:J21),G21:J21,0)),"") -> Ferguson
